Workbook

Sheet 표지
A1: 서울회생법원 제○○부(○)
A2: ="사건번호: "&O3&" "&O4 -> 사건번호: 20○○회합100○○○ 회생 | N2: 기초입력
N3: 사건번호 | O3: 20○○회합100○○○
A4: =IF($O$7="개인","회생담보권, 회생채권, 벌금·조세채권의 목록","회생담보권, 회생채권, 벌금·조세채권자, 주식·지분권자의 목록") -> 회생담보권, 회생채권, 벌금·조세채권자, 주식·지분권자의 목록 | N4: 사건 | O4: =IF(MID(O3,5,1)="간","간이회생","회생") -> 회생 | P4: 자동입력
N5: 채무자 | O5: ○○○○ 주식회사
N6: 법률상관리인 | O6: ○○○ | P6: 개인 사건엔 기입 X
A7: 20○○. ○○. ○○. | N7: 개인/법인 | O7: 법인
A10: =IF($O$7="개인","채무자(법률상관리인) ","채무자 ")&O5 -> 채무자 ○○○○ 주식회사
A11: =IF($O$7="개인","","법률상관리인 "&O6) -> 법률상관리인 ○○○

Sheet 목차
A1: 목 차
A3: 1. | B3: 목록 작성 기준 | D3: -------------------------------------------------------------------------- | G3: 1
A4: 2. | B4: =IF(표지!$O$7="개인","회생담보권자, 회생채권자, 벌금·조세채권자의 목록 총괄표","회생담보권자, 회생채권자, 벌금·조세채권자, 주주·지분권자의 목록 총괄표") -> 회생담보권자, 회생채권자, 벌금·조세채권자, 주주·지분권자의 목록 총괄표 | F4: ------------------------------------- | G4: 2
A5: 3. | B5: 회생담보권의 목록 총괄표 | D5: -------------------------------------------------------------------------- | G5: 4
A6: 4. | B6: 담보물 배분표 | D6: -------------------------------------------------------------------------- | G6: 6
A7: 5. | B7: 담보권자의 목록 | D7: -------------------------------------------------------------------------- | G7: 8
A8: 6. | B8: 회생채권자의 목록 총괄표 | D8: -------------------------------------------------------------------------- | G8: 10
A9: 7. | B9: 회생채권자의 목록 | D9: -------------------------------------------------------------------------- | G9: 30
A10: 8. | B10: 벌금 · 조세채권자의 목록 총괄표 | D10: -------------------------------------------------------------------------- | G10: 131
A11: 9. | B11: 벌금 · 조세채권자의 목록 | D11: -------------------------------------------------------------------------- | G11: 133
A12: 10. | B12: 주주 지분권자의 목록 총괄표 | D12: -------------------------------------------------------------------------- | G12: 137 | H12: 개인 사건은 숨기기
A13: 11. | B13: 주주 지분권자의 목록 | D13: -------------------------------------------------------------------------- | G13: 139 | H13: 개인 사건은 숨기기
A14: 별첨 : 감정평가서, 등기부등본, 인터넷차량시세표, 어음발행 명세
A17: 법인 | B17: 회생담보권자, 회생채권자, 벌금·조세채권자, 주주·지분권자의 목록 총괄표
A18: 개인 | B18: 회생담보권자, 회생채권자, 벌금·조세채권자의 목록 총괄표

Sheet 목록작성기준
A1: 1. 목록 작성 기준
A4: * 본 목록표 작성은 회생절차 개시결정일인 2024년 07월 31일 기준으로 작성하였습니다.
A7: * 회생담보권 및 회생채권의 개시전 이자는 개시결정일 전일인 2024년 07월 30일까지 발생한 금액을 기준으로 계산하였습니다.
A10: * 조세채권의 목록 작성 기준일 확인된 사항만 기재하였습니다.
D21: ㅁ

Sheet 목록총괄표
A1: =A2 -> 2. 회생담보권자, 회생채권자, 벌금·조세채권자, 주주·지분권자의 목록
A2: =IF(표지!$O$7="개인",목록총괄표!B22,목록총괄표!B21) -> 2. 회생담보권자, 회생채권자, 벌금·조세채권자, 주주·지분권자의 목록
A3: ="채무자: "&표지!$O$5 -> 채무자: ○○○○ 주식회사 | F3: (단위: 원)
A4: 구 분 | C4: 건 수 | D4: 금 액 | E4: 비 고
A5: 회생담보권 | C5: =MAX(담보권총괄표!A5:A29) -> 1 | D5: 0 | E5: 회생담보권 중 회생채권 인정액 : | F5: =담보권총괄표!K33 -> 2700000000
A6: 회생채권 | B6: 대여금채권 | C6: 7 | D6: 3148591704
B7: 구상채권 | C7: 1 | D7: 850000000
B8: 상거래채권 | C8: 75 | D8: 3.9941121e+09 | E8: 1,043,537달러 포함
B9: 특수관계인채권 | C9: 5 | D9: 399763553
B10: 회생담보권 중 회생채권 인정액 | C10: =MAX(담보권총괄표!A10:A34) -> 0 | D10: 0
B11: 상거래채권 | C11: 3 | D11: 262171231
B12: 회생채권 | C12: 89 | D12: =회생채권총괄!G542 -> 8820155859
B13: 회생담보권 중 회생채권 인정액 | C13: (1) | D13: =F5 -> 2700000000
B14: 소계 | C14: 89 | D14: =D12+D13 -> 11520155859
A15: 합 계 | C15: =C5+C12 -> 90 | D15: =SUM(D5,D14) -> 11520155859
A17: 조세등 채권 | C17: 2 | D17: =조세총괄!G35 -> 61794850 | E17: 조사대상 아님
A18: 주주·지분권 | C18: =MAX(주주총괄!C5:C8) -> 4 | D18: =주주총괄!H9 -> 1500000000 | E18: =TEXT(주주총괄!G9,"###,###주")&", 1주당 금액 "&TEXT(주주총괄!L4,"###,###원")&", 조사대상 아님" -> 15,000,000주, 1주당 금액 100원, 조사대상 아님 | G18: 개인 채무자면 숨기기
A21: 법인 | B21: 2. 회생담보권자, 회생채권자, 벌금·조세채권자, 주주·지분권자의 목록
A22: 개인 | B22: 2. 회생담보권자, 회생채권자, 벌금·조세채권자의 목록

Sheet 담보권총괄표
A1: =B2 -> 3. 회생담보권의 목록 총괄표
B2: 3. 회생담보권의 목록 총괄표
A3: ="채무자: "&표지!$O$5 -> 채무자: ○○○○ 주식회사 | N3: (단위: 원)
A4: 순번 | B4: 목록번호 | C4: 담보권자 | D4: 주소 | E4: 담보권 종류 및 목적물 | F4: 가치평가 및 배분 | G4: 채권내용 | H4: 채권액 | I4: 담보권인정액 | J4: 의결권인정액 | K4: 회생채권 인정액 | L4: 회생채권 의결권인정액 | M4: 우선권 | N4: 비 고
A5: 1 | B5: 담보1 | C5: **은행(은행장 ***) | D5: 서울특별시 ***구 **로 ** | E5: [근저당권] | F5: 총평가액 0원 선순위배분액 0원 당배분액 0원 배분후잔액 0원 | G5: 대여금채권 | N5: 감정 미실시로 담보배분은 유보함.
E6: (1) 경기도 ***시 **동 *** 대지 | G6: 1. 원금 | H6: 2700000000 | K6: 2700000000 | L6: 2700000000
E7: (2) **도 ***시 **동 *** 건물
G8: 2. 개시전 이자
E9: 채권최고액: 3,960,000,000원
E10: 설정순위: 1순위, 2순위 | G10: 3. 개시후 이자
G17: 소계 | H17: =H6+H8+H10 -> 2700000000 | I17: =I6+I8+I10 -> 0 | J17: =J6+J8+J10 -> 0
A30: 회생담보권 합계 | G30: 1.원금 | H30: =H6+H19 -> 2700000000 | K30: =K6+K19 -> 2700000000 | L30: =L6+L19 -> 2700000000
G31: 2.개시전 이자
G32: 3.개시후 이자
G33: 합 계 | H33: =H30 -> 2700000000 | K33: =K30 -> 2700000000 | L33: =L30 -> 2700000000

Sheet 담보배분표
A1: 4. 담보물 배분표
A2: 4. 담보물 배분표
A3: ="채무자: "&표지!$O$5 -> 채무자: ○○○○ 주식회사 | N3: (단위: 원)
A4: 담보물 소재지 | C4: 토지면적/ 건물면적 | E4: 담보설정현황 | I4: 가치평가액 | J4: 배분표 | N4: 비고 | O4: 기계기구 | Q4: 공장 및 광업재단
E5: 순위 | F5: 설정일자 | G5: 채권자 | H5: 공담 | J5: 설정자 | K5: 설정금액 | L5: 배분액 | M5: 배분잔액
A6: (1) **도 ***시 **동 *** 대지 | C6: 647.6㎡ | E6: 1 | F6: 2021.3.31. | G6: ***은행 | K6: 3240000000 | N6: 감정 미실시로 담보배분은 유보함.
A7: (2) **도 ***시 **동 *** 건물 | C7: 658.27㎡ | E7: 2 | F7: 2022.5.20. | G7: ***은행 | K7: 720000000
A13: 합 계 | I13: 미정 | K13: =SUM(K6:K7) -> 3960000000

Sheet 담보권자의 목록
A1: =A2 -> 5. 담 보 권 자 의 목 록
A2: 5. 담 보 권 자 의 목 록 | I2: 4. 담 보 권 자 의 목 록
A3: 사 건 | C3: =표지!$O$3&" "&표지!O4 -> 20○○회합100○○○ 회생 | F3: 채무자 | G3: =표지!$O$5 -> ○○○○ 주식회사
A4: 회생 채권자 | B4: 성명·명칭 | C4: =담보권총괄표!C5 -> **은행(은행장 ***)
B5: 주 소 | C5: =담보권총괄표!D5 -> 서울특별시 ***구 **로 **
B6: 전화번호 | F6: e-mail
A7: 목록번호 | C7: =담보권총괄표!B5 -> 담보1 | F7: 신고번호
A8: 담보권의 원인·내용 | C8: (원인) | D8: =담보권총괄표!G5 -> 대여금채권
C9: (내용) | D9: ■ | E9: 원금 | F9: =담보권총괄표!H6 -> 2700000000 | G9: 원
D10: ■ | E10: 개시전 이자 | F10: =담보권총괄표!H8 -> 0 | G10: 원
A12: 담보권의 목적·가액 | C12: 목적 | E12: (1)***시 **동 *** 대지 (2)***시 **동 *** 건물
C13: 가액 | F13: 0 | G13: 원
A14: 회생담보권 인정액 | F14: =담보권총괄표!I6 -> 0 | G14: 원
A15: 의결권 액 | F15: =담보권총괄표!J6 -> 0 | G15: 원
A16: 집행권원, 종국판결 유무
A17: 소송 계속 여부
A18: 비고 | C18: =담보권총괄표!N5 -> 감정 미실시로 담보배분은 유보함.

Sheet 회생채권자요약
A1: 순번 | B1: 유형 | C1: 채권번호 | D1: 채권자 | E1: 채권자 주소 | F1: 우편번호 | G1: 발생일 | H1: 채권 내용 | I1: 채권액 (원금) | J1: 채권액 (개시전 이자) | K1: 의결권인정액 (원금) | L1: 의결권인정액 (개시전 이자) | M1: 우선권 | N1: 비고
A2: 1 | B2: 채권 | C2: 1-1 | D2: 중소기업은행(은행장: 김성태) | E2: 서울 중구 을지로 79 | F2: 04541 | G2: 2017.08.31. | H2: 대여금채권 | I2: 300000000 | J2: ="" | K2: =I2 -> 300000000 | N2: 2017.08.31.자 중소기업자금대출 신용보증기금 보증서 발행 보증기간: 2017.08.31.~2023.08.25. 보증금액: 270,000,000(비율 90%)
A3: 1 | B3: 채권 | C3: 1-2 | D3: 중소기업은행(은행장: 김성태) | E3: 서울 중구 을지로 79 | F3: 04541 | G3: 2022.05.31. | H3: 대여금채권 | I3: 399550769 | K3: =I3 -> 399550769 | N3: 2022.05.31.자 중소기업자금대출
A4: 1 | B4: 채권 | C4: 1-3 | D4: 중소기업은행(은행장: 김성태) | E4: 서울 중구 을지로 79 | F4: 04541 | G4: 2022.05.31. | H4: 대여금채권 | I4: 40674000 | K4: =I4 -> 40674000 | N4: 2022.05.31.자 중소기업자금대출 4억 원 중 40,674,000원 신용대출
A5: 1 | B5: 채권 | C5: 1-4 | D5: 중소기업은행(은행장: 김성태) | E5: 서울 중구 을지로 79 | F5: 04541 | G5: 2022.09.19. | H5: 대여금채권 | I5: 340000000 | K5: =I5 -> 340000000 | N5: 2022.09.19.자 중소기업자금대출
A6: 1 | B6: 채권 | C6: 1-5 | D6: 중소기업은행(은행장: 김성태) | E6: 서울 중구 을지로 79 | F6: 04541 | G6: 2023.04.01. | H6: 대여금채권 | I6: 25930990 | K6: =I6 -> 25930990 | N6: 신용카드 사용대금
D7: 중소기업은행 합계 | I7: =SUM(I2:I6) -> 1106155759 | J7: =SUM(J2:J6) -> 0 | K7: =SUM(K2:K6) -> 1106155759
A8: 2 | B8: 채권 | C8: 2-1 | D8: ㈜우리은행(은행장: 이원덕) | E8: 서울 중구 소공로 51 | F8: 04632 | G8: 2015.06.02. | H8: 대여금채권 | I8: 380000000 | K8: =I8 -> 380000000 | N8: 2015.06.02.자 운영자금대출 신용보증기간 보증서 발행 보증금액: 323,000,000(보증비율 85%)
A9: 2 | B9: 채권 | C9: 2-2 | D9: ㈜우리은행(은행장: 이원덕) | E9: 서울 중구 소공로 51 | F9: 04632 | G9: 2013.03.26. | H9: 대여금채권 | I9: 150000000 | K9: =I9 -> 150000000 | N9: 2013.03.26.자 운영자금대출 신용보증기간 보증서 발행 보증금액: 135,000,000(보증비율 90%)
A10: 2 | B10: 채권 | C10: 2-3 | D10: ㈜우리은행(은행장: 이원덕) | E10: 서울 중구 소공로 51 | F10: 04632 | G10: 2022.05.20. | H10: 대여금채권 | I10: 259000000 | K10: =I10 -> 259000000 | N10: 2022.05.20.자 운영자금대출
A11: 2 | B11: 채권 | C11: 2-4 | D11: ㈜우리은행(은행장: 이원덕) | E11: 서울 중구 소공로 51 | F11: 04632 | G11: 2011.09.22. | H11: 대여금채권 | I11: 300000000 | K11: =I11 -> 300000000 | N11: 2011.09.22.자 운영자금대출 신용보증기간 보증서 발행 보증금액: 255,000,000(보증비율 85%)
D12: ㈜우리은행 합계 | I12: =SUM(I8:I11) -> 1089000000 | J12: =SUM(J8:J11) -> 0 | K12: =SUM(K8:K11) -> 1089000000
A13: 3 | B13: 채권 | C13: 3 | D13: ㈜국민은행(은행장: 이재근) | E13: 서울 영등포구 국제금융로8길 26 | F13: 07331 | G13: 2022.07.01. | H13: 대여금채권 | I13: 350000000 | K13: =I13 -> 350000000 | N13: 2022.07.11.자 자금대출 신용보증기간 보증서 발행 보증금액: 297,500,000(보증비율 85%)
A14: 4 | B14: 채권 | C14: 4 | D14: 중소벤쳐기업진흥공단(이사장: 김학도) | E14: 경남 진주시 동진로 430 | F14: 52851 | G14: 2020.03.13. | H14: 대여금채권 | I14: 95680000 | K14: =I14 -> 95680000 | N14: 2022.03.13.자 운영자금대출
A15: 5 | B15: 채권 | C15: 5 | D15: 케이비캐피탈㈜(대표이사: 황수남) | E15: 경기 수원시 팔달구 효원로 295 | F15: 16488 | G15: 2023.05.31. | H15: 대여금채권 | I15: 5087769 | K15: =I15 -> 5087769 | N15: 2023.05.31.자 자동차(그랜져HG) 운용리스 위약금
A16: 6 | B16: 채권 | C16: 6 | D16: 신한카드㈜(대표이사: 문동권) | E16: 서울 중구 을지로 100, A동 | F16: 04551 | G16: 2023.05.31. | H16: 대여금채권 | I16: 48730764 | K16: =I16 -> 48730764 | N16: 2023.05.31.자 자동차(제네시스G90) 운용리스 위약금
A17: 7 | B17: 채권 | C17: 7 | D17: ㈜우리카드(대표이사: 박완식) | E17: 서울 종로구 종로1길 50 | F17: 03142 | G17: 2023.04.01. | H17: 대여금채권 | I17: 17036203 | K17: =I17 -> 17036203 | N17: 신용카드 사용대금
A18: 8 | B18: 채권 | C18: 8 | D18: ㈜케이비국민카드(대표이사: 이창권) | E18: 서울 종로구 새문안로3길 30 | F18: 03173 | G18: 2023.04.01. | H18: 대여금채권 | I18: 16455827 | K18: =I18 -> 16455827 | N18: 신용카드 사용대금
A19: 9 | B19: 채권 | C19: 9 | D19: 하나카드㈜(대표이사: 이호성) | E19: 서울 중구 을지로 66 | F19: 04538 | G19: 2023.04.01. | H19: 대여금채권 | I19: 57970547 | K19: =I19 -> 57970547 | N19: 신용카드 사용대금
A20: 10 | B20: 채권 | C20: 10 | D20: 박영민 | E20: 경기 화성시 10용사로 221, 105동 1004호 | F20: 18417 | G20: 2022.12.12. | H20: 대여금채권 | I20: 84919510 | K20: =I20 -> 84919510 | N20: 2022.12.12. 차용금
A21: 11 | B21: 채권 | C21: 11 | D21: ㈜신신포장(대표이사: 오정식) | E21: 경기 부천시 석천로453번길 64-12 | F21: 14445 | G21: 2013.01.05. | H21: 상거래채권 | I21: 127770818 | K21: =I21 -> 127770818 | N21: 발생기간: 2023.01.05.
A22: 12 | B22: 채권 | C22: 12 | D22: 김지환(경진산업) | E22: 경기 김포시 양촌읍 황금로273번길 34 | F22: 10049 | G22: 2013.01.03. | H22: 상거래채권 | I22: 784871312 | K22: =I22 -> 784871312 | N22: 발생기간: 2023.01.03.
A23: 13 | B23: 채권 | C23: 13 | D23: 김중훈(삼원그라텍) | E23: 경기 화성시 팔탄면 현대기아로 15-27, 123호 | F23: 18576 | G23: 2013.01.15. | H23: 상거래채권 | I23: 52134871 | K23: =I23 -> 52134871 | N23: 발생기간: 2023.01.15.
A24: 14 | B24: 채권 | C24: 14 | D24: 오희석(태양고무) | E24: 서울 구로구 구로중앙로 197, C열 17동 124호 | F24: 08216 | G24: 2023.02.16. | H24: 상거래채권 | I24: 385000 | K24: =I24 -> 385000 | N24: 발생기간: 2023.02.16.
A25: 15 | B25: 채권 | C25: 15 | D25: 구무회(금화엔지니어링) | E25: 서울 구로구 경인로55길 51, B동 118호 | F25: 08215 | G25: 2022.08.08. | H25: 상거래채권 | I25: 13152360 | K25: =I25 -> 13152360 | N25: 발생기간: 2022.08.08.
A26: 16 | B26: 채권 | C26: 16 | D26: 장두경(삼성스프링) | E26: 경기 화성시 팔탄면 시청로 934-3, E동 206호 | F26: 18529 | G26: 2023.04.04. | H26: 상거래채권 | I26: 2420000 | K26: =I26 -> 2420000 | N26: 발생기간: 2023.04.04.
... A40: 30 | B40: 채권 | C40: 30 | D40: ㈜우진플라임(대표이사: 김익환) | E40: 인천 서구 로봇랜드로249번길 46-17 | F40: 22756 | G40: 2022.11.28. | H40: 상거래채권 | I40: 9770000 | K40: =I40 -> 9770000 | N40: 발생기간: 2022.11.28.
A41: 31 | B41: 채권 | C41: 31 | D41: ㈜동양전기안전관리(대표이사: 박현철) | E41: 경기 고양시 일산동구 무궁화로 43-15, 203동 6호 | F41: 10364 | G41: 2022.04.25. | H41: 상거래채권 | I41: 11570000 | J41: ="" | K41: =I41 -> 11570000 | N41: 발생기간: 2022.04.25.
A42: 32 | B42: 채권 | C42: 32 | D42: 이종근 | E42: 경기 파주시 월롱면 통일로 642번길 96 | F42: 10945 | G42: 2018.12.28. | H42: 특수관계인채권 | I42: 86659693 | K42: =I42 -> 86659693 | N42: 발생기간: 2018.12.28.~2023.05.17. 가수금(관계: 대표자)
A43: 33 | B43: 채권 | C43: 33 | D43: 전소영 | E43: 인천 계양구 효서로 381, 212동 1510호 | F43: 21125 | G43: 2015.02.12. | H43: 특수관계인채권 | I43: 59870810 | K43: =I43 -> 59870810 | N43: 발생기간: 2015.02.12.~2023.05.17. 가수금(관계: 대표자의 배우자)
D44: 회생채권 합계 | I44: =SUM(I2:I6,I8:I11,I13:I43) -> 4343098809 | J44: =SUM(J2:J6,J8:J11,J13:J43) -> 0 | K44: =SUM(K2:K6,K8:K11,K13:K43) -> 4343098809
G46: =COUNTIF($H$2:$H$43,H46)-7 -> 10 | H46: 대여금채권 | I46: =SUMIF($H$2:$H$44,$H46,I$2:I$44) -> 2871036379 | J46: =SUMIF($H$2:$H$44,$H46,J$2:J$44) -> 0 | K46: =SUMIF($H$2:$H$44,$H46,K$2:K$44) -> 2871036379
G47: =COUNTIF($H$2:$H$43,H47) -> 0 | I47: =SUMIF($H$2:$H$44,$H47,I$2:I$44) -> 0 | J47: =SUMIF($H$2:$H$44,$H47,J$2:J$44) -> 0 | K47: =SUMIF($H$2:$H$44,$H47,K$2:K$44) -> 0
G48: =COUNTIF($H$2:$H$43,H48) -> 21 | H48: 상거래채권 | I48: =SUMIF($H$2:$H$44,$H48,I$2:I$44) -> 1325531927 | J48: =SUMIF($H$2:$H$44,$H48,J$2:J$44) -> 0 | K48: =SUMIF($H$2:$H$44,$H48,K$2:K$44) -> 1325531927
G49: =COUNTIF($H$2:$H$43,H49) -> 2 | H49: 특수관계인채권 | I49: =SUMIF($H$2:$H$44,$H49,I$2:I$44) -> 146530503 | J49: =SUMIF($H$2:$H$44,$H49,J$2:J$44) -> 0 | K49: =SUMIF($H$2:$H$44,$H49,K$2:K$44) -> 146530503
G50: =SUM(G46:G49) -> 33 | H50: 총합 | I50: =SUM(I46:I49) -> 4343098809 | J50: =SUM(J46:J49) -> 0 | K50: =SUM(K46:K49) -> 4343098809

Sheet 회생채권총괄
A1: =B2 -> 6. 회생채권자의 목록 총괄표
B2: 6. 회생채권자의 목록 총괄표
A4: ="채무자: "&표지!$O$5 -> 채무자: ○○○○ 주식회사 | J4: (단위: 원)
A5: 순번 | B5: 목록번호 | D5: 채권자 | E5: 주소 | F5: 채권내용 | G5: 채권액 | H5: 의결권인정액 | I5: 우선권 | J5: 비고
A6: 1 | B6: 채권 | C6: 1-1 | D6: ****은행 (은행장 ***) | E6: 서울특별시 **구 **로 ** | F6: 대여금채권 | J6: 신용보증기금보증서 담보
F7: 1. 원금 | G7: 506000000 | H7: =G7 -> 506000000 | L7: 1. 원금
F8: 2. 개시전 이자 | H8: =G8 -> 0 | L8: 2. 개시전 이자 | O8: 1) 57,584,184원
O9: 2) 36,053,287원
F10: =IF(OR(MID(C6,2,1)="-",MID(C6,3,1)="-",MID(C6,4,1)="-",MID(47,5,1)="-"),"소계","합계") -> 소계 | G10: =SUM(G7:G9) -> 506000000 | H10: =SUM(H7:H9) -> 506000000
B11: 채권 | C11: 1-2 | F11: 대여금채권
F12: 1. 원금 | G12: 97226722 | H12: =G12 -> 97226722
F13: 2. 개시전 이자 | H13: =G13 -> 0
F15: =IF(OR(MID(C11,2,1)="-",MID(C11,3,1)="-",MID(C11,4,1)="-",MID(47,5,1)="-"),"소계","합계") -> 소계 | G15: =SUM(G12:G13) -> 97226722 | H15: =SUM(H12:H13) -> 97226722
B16: 채권 | C16: 1-3 | F16: 대여금채권 | J16: 신용보증기금보증서 담보
F17: 1. 원금 | G17: 256000000 | H17: =G17 -> 256000000 | L17: 1. 원금
F18: 2. 개시전 이자 | H18: =G18 -> 0 | L18: 2. 개시전 이자 | O18: 1) 57,584,184원
O19: 2) 36,053,287원
F20: =IF(OR(MID(C16,2,1)="-",MID(C16,3,1)="-",MID(C16,4,1)="-",MID(47,5,1)="-"),"소계","합계") -> 소계 | G20: =SUM(G17:G19) -> 256000000 | H20: =SUM(H17:H19) -> 256000000
B21: 채권 | C21: 1-4 | F21: 대여금채권
F22: 1. 원금 | G22: 99990000 | H22: =G22 -> 99990000
F23: 2. 개시전 이자 | H23: =G23 -> 0
F25: =IF(OR(MID(C21,2,1)="-",MID(C21,3,1)="-",MID(C21,4,1)="-",MID(47,5,1)="-"),"소계","합계") -> 소계 | G25: =SUM(G22:G23) -> 99990000 | H25: =SUM(H22:H23) -> 99990000
B26: 채권 | C26: 1-5 | F26: 대여금채권
F27: 1. 원금 | G27: 498827527 | H27: =G27 -> 498827527 | L27: 1. 원금
F28: 2. 개시전 이자 | H28: =G28 -> 0 | L28: 2. 개시전 이자 | O28: 1) 57,584,184원
O29: 2) 36,053,287원
F30: =IF(OR(MID(C26,2,1)="-",MID(C26,3,1)="-",MID(C26,4,1)="-",MID(47,5,1)="-"),"소계","합계") -> 소계 | G30: =SUM(G27:G29) -> 498827527 | H30: =SUM(H27:H29) -> 498827527
B31: 채권 | C31: 1-6 | F31: 대여금채권
F32: 1. 원금 | G32: 500000000 | H32: =G32 -> 500000000
F33: 2. 개시전 이자 | H33: =G33 -> 0
F35: =IF(OR(MID(C31,2,1)="-",MID(C31,3,1)="-",MID(C31,4,1)="-",MID(47,5,1)="-"),"소계","합계") -> 소계 | G35: =SUM(G32:G33) -> 500000000 | H35: =SUM(H32:H33) -> 500000000
B36: 채권 | C36: 1-7 | F36: 대여금채권
F37: 1. 원금 | G37: 497203787 | H37: =G37 -> 497203787 | L37: 1. 원금
F38: 2. 개시전 이자 | H38: =G38 -> 0 | L38: 2. 개시전 이자 | O38: 1) 57,584,184원
O39: 2) 36,053,287원
F40: =IF(OR(MID(C36,2,1)="-",MID(C36,3,1)="-",MID(C36,4,1)="-",MID(47,5,1)="-"),"소계","합계") -> 소계 | G40: =SUM(G37:G39) -> 497203787 | H40: =SUM(H37:H39) -> 497203787
B41: 채권 | C41: 1-8 | F41: 대여금채권
F42: 1. 원금 | G42: 120000000 | H42: =G42 -> 120000000
F43: 2. 개시전 이자 | H43: =G43 -> 0
F45: =IF(OR(MID(C41,2,1)="-",MID(C41,3,1)="-",MID(C41,4,1)="-",MID(47,5,1)="-"),"소계","합계") -> 소계 | G45: =SUM(G42:G43) -> 120000000 | H45: =SUM(H42:H43) -> 120000000
...

Sheet 회생채권개별
A1: 7. 회 생 채 권 자 의 목 록
A2: 7. 회 생 채 권 자 의 목 록 | I2: 7. 회 생 채 권 자 의 목 록
A4: 사 건 | C4: 20OO회합100OOO 회생 | F4: 채무자 | G4: OOOO 주식회사 | I4: 기본 높이 31.5
A5: 회생 채권자 | B5: 성명·명칭
B6: 주 소
B7: 전화번호 | F7: e-mail
A8: 목록번호 | C8: 1-1 | F8: 신고번호
A9: 회생채권의 원인·내용 | C9: (원인) | F9: =회생채권총괄!F6 -> 대여금채권
C10: (내용) | D10: ■ | E10: 원금 | F10: 506000000 | G10: 원
D11: ■ | E11: 개시전 이자 | F11: =회생채권총괄!G8 -> 0 | G11: 원
A13: 우선권 유무 | G13: 원
A14: 의결권 액 | F14: =F10 -> 506000000 | G14: 원
A15: 비고 | I15: 여기까지 1개 | J15: 1~23 끌어내리기
A16: 목록번호 | C16: 1-2 | F16: 신고번호
A17: 회생채권의 원인·내용 | C17: (원인) | D17: 대여금채권
C18: (내용) | D18: ■ | E18: 원금 | F18: 97226722 | G18: 원
D19: ■ | E19: 개시전 이자 | G19: 원
A21: 우선권 유무 | G21: 원
A22: 의결권 액 | G22: 원
A23: 비고 | I23: 여기까지 1개 | J23: 1~23 끌어내리기
A24: 목록번호 | C24: 1-3 | F24: 신고번호
A25: 회생채권의 원인·내용 | C25: (원인) | F25: 대여금채권
C26: (내용) | D26: ■ | E26: 원금 | F26: 256000000 | G26: 원
D27: ■ | E27: 개시전 이자 | G27: 원
A29: 우선권 유무 | G29: 원
A30: 의결권 액 | F30: =F26 -> 256000000 | G30: 원
A31: 비고 | I31: 여기까지 1개 | J31: 1~23 끌어내리기
A32: 목록번호 | C32: 1-4 | F32: 신고번호
A33: 회생채권의 원인·내용 | C33: (원인) | F33: 대여금채권
C34: (내용) | D34: ■ | E34: 원금 | F34: 99990000 | G34: 원
D35: ■ | E35: 개시전 이자 | F35: =회생채권총괄!G62 -> 0 | G35: 원
A37: 우선권 유무 | G37: 원
A38: 의결권 액 | F38: =F34 -> 99990000 | G38: 원
A39: 비고 | I39: 여기까지 1개 | J39: 1~23 끌어내리기
A40: 목록번호 | C40: 1-5 | F40: 신고번호
A41: 회생채권의 원인·내용 | C41: (원인) | F41: 대여금채권
C42: (내용) | D42: ■ | E42: 원금 | F42: 498827527 | G42: 원
D43: ■ | E43: 개시전 이자 | F43: =회생채권총괄!G70 -> 0 | G43: 원
A45: 우선권 유무 | G45: 원
A46: 의결권 액 | F46: =F42 -> 498827527 | G46: 원
...

Sheet 조세총괄
A1: =A2 -> 8. 벌금 · 조세채권자의 목록 총괄표
A2: 8. 벌금 · 조세채권자의 목록 총괄표
A3: ="채무자: "&표지!$O$5 -> 채무자: ○○○○ 주식회사 | H3: (단위: 원)
A4: 순번 | B4: 목록번호 | D4: 채권자 | E4: 주소 | F4: 채권내용 | G4: 채권액 | H4: 비고
A5: 1 | B5: 조세등 | C5: 1 | D5: OOO세무서 | E5: OO시 OO로 OO (OO동 OOO-2) | F5: 부가가치세 | H5: 2023년 2기 확정 부가가치세 및 2024년 1기 예정 부가가치세 | J5: 25000000
F6: 본세 | G6: 44000000 | J6: 19000000
F7: 가산세 | J7: =SUM(J5:J6) -> 44000000
F8: 소계 | G8: =SUM(G6:G7) -> 44000000
A9: 2 | B9: 조세등 | C9: 2-1 | D9: 국민건강보험공단 서울강원지역본부 (이사장 OOO) | E9: OO도 OO시 OO로 OO | F9: 건강보험료
F10: 본세 | G10: 7524910
F11: 가산세
F12: 소계 | G12: =SUM(G10:G11) -> 7524910
B13: 조세등 | C13: 2-2 | F13: 요양보험료
F14: 본세
F15: 가산세
F16: 소계 | G16: =SUM(G14:G15) -> 0
B17: 조세등 | C17: 2-2 | F17: 연금보험료
F18: 본세 | G18: 8557140
F19: 가산세
F20: 소계 | G20: =SUM(G18:G19) -> 8557140
B21: 조세등 | C21: 2-3 | F21: 고용보험료
F22: 본세 | G22: 1712800
F23: 가산세
F24: 소계 | G24: =SUM(G22:G23) -> 1712800
B25: 조세등 | C25: 2-5 | F25: 산재보험료
F26: 본세
F27: 가산세
F28: 소계 | G28: =SUM(G26:G27) -> 0
B29: 국민건강보험공단 소계
F30: 본세 | G30: =SUMIF(F9:F28,$F30,G9:G28) -> 17794850
F31: 가산세 | G31: =SUMIF(F9:F28,$F31,G9:G28) -> 0
F32: 소계 | G32: =SUM(G30:G31) -> 17794850
A33: 조세등 채권의 합계 | F33: 본세 | G33: =G6+G30 -> 61794850
F34: 가산세 | G34: =G7+G31 -> 0
F35: 소계 | G35: =SUM(G33:G34) -> 61794850

Sheet 조세목록
A1: =A2 -> 9. 벌금 · 조세채권자의 목록
A2: 9. 벌금 · 조세채권자의 목록
A4: 사 건 | C4: =표지!$O$3&" "&표지!$O$4 -> 20○○회합100○○○ 회생 | F4: 채무자 | G4: =표지!$O$5 -> ○○○○ 주식회사
A5: 청구 권자 | B5: 성명. 명칭 | C5: =조세총괄!D5 -> OOO세무서 | I5: 여기서부터 끌기
B6: 주 소 | C6: =조세총괄!E5 -> OO시 OO로 OO (OO동 OOO-2)
B7: 전화번호 | F7: e-mail
A8: 목록번호 | C8: 조세등 | E8: 1 | F8: 신고번호
A9: 청구채권의 원인·내용 | C9: (원인) | D9: =조세총괄!F5 -> 부가가치세 | F9: (2023년 2기 및 2024년 1기)
C10: (내용) | D10: ■ | E10: 본 세 | F10: =조세총괄!G6 -> 44000000 | G10: 원
D11: ■ | E11: 가 산 세 | G11: 원
D12: ■ | E12: 총 체납금 | F12: =SUM(F10:F11) -> 44000000 | G12: 원
A13: 목록번호 | C13: 조세등 | F13: 신고번호
A14: 청구채권의 원인·내용 | C14: (원인)
C15: (내용) | D15: ■ | E15: 본 세 | G15: 원
D16: ■ | E16: 가 산 세 | G16: 원
D17: ■ | E17: 총 체납금 | G17: 원
A18: 집행권원, 종국판결 유무
A19: 행정심판, 소송 계속 여부
A20: 비고
A21: 9. 벌금 · 조세채권자의 목록
A23: 청구 권자 | B23: 성명. 명칭 | C23: =조세총괄!D9 -> 국민건강보험공단 서울강원지역본부 (이사장 OOO) | I23: 여기서부터 끌기
B24: 주 소 | C24: =조세총괄!E9 -> OO도 OO시 OO로 OO
B25: 전화번호 | F25: e-mail
A26: 목록번호 | C26: 조세등 | E26: 2-1 | F26: 신고번호
A27: 청구채권의 원인·내용 | C27: (원인) | D27: =조세총괄!F9 -> 건강보험료
C28: (내용) | D28: ■ | E28: 본 세 | F28: =조세총괄!G10 -> 7524910 | G28: 원
D29: ■ | E29: 가 산 세 | G29: 원
D30: ■ | E30: 총 체납금 | F30: =SUM(F28:F29) -> 7524910 | G30: 원
A31: 목록번호 | C31: 조세등 | E31: 2-2 | F31: 신고번호
A32: 청구채권의 원인·내용 | C32: (원인) | D32: =조세총괄!F17 -> 연금보험료
C33: (내용) | D33: ■ | E33: 본 세 | F33: =조세총괄!G18 -> 8557140 | G33: 원
D34: ■ | E34: 가 산 세 | G34: 원
D35: ■ | E35: 총 체납금 | F35: =SUM(F33:F34) -> 8557140 | G35: 원
A36: 목록번호 | C36: 조세등 | E36: 2-3 | F36: 신고번호
A37: 청구채권의 원인·내용 | C37: (원인) | D37: =조세총괄!F21 -> 고용보험료
C38: (내용) | D38: ■ | E38: 본 세 | F38: =조세총괄!G22 -> 1712800 | G38: 원
D39: ■ | E39: 가 산 세 | G39: 원
D40: ■ | E40: 총 체납금 | F40: =SUM(F38:F39) -> 1712800 | G40: 원
A41: 목록번호 | C41: 조세등 | E41: 2-4 | F41: 신고번호
A42: 청구채권의 원인·내용 | C42: (원인) | D42: =조세총괄!F25 -> 산재보험료
...

Sheet 주주총괄
A1: =A2 -> 10. 주주 지분권자의 목록 총괄표
A2: 10. 주주 지분권자의 목록 총괄표
A3: ="채무자: "&표지!$O$5 -> 채무자: ○○○○ 주식회사 | J3: ="(단위: 원, 주 / 주당 액면가: "&TEXT(L4,"###,###")&"원)" -> (단위: 원, 주 / 주당 액면가: 100원)
A4: 순번 | B4: 목록번호 | D4: 주주·지분권자 | E4: 주 소 | F4: 주식·출자지분의 종류 | G4: 주식 수 | H4: 출자지분의 액수 | I4: 지분율 | J4: 비고 | K4: 1주당 발행가액 | L4: 100
A5: 1 | B5: 주식 | C5: =A5 -> 1 | D5: OO광 | E5: OO도 OOO시 OO읍 OO로OOO번길 OO OO아파트 OOO동 OOO호 | F5: 보통주 | G5: 7442400 | H5: =G5*$L$4 -> 744240000 | I5: =H5/$H$9 -> 0.49616
A6: 2 | B6: 주식 | C6: =A6 -> 2 | D6: OO영 | E6: OO시 OO구 OOOO2로 OO OOO동 OOOO호 | F6: 보통주 | G6: 6227200 | H6: =G6*$L$4 -> 622720000 | I6: =H6/$H$9 -> 0.41514667
A7: 3 | B7: 주식 | C7: =A7 -> 3 | D7: OO훈 | E7: 경기 OO시 OO읍 OO로 OOO, OOO동 OOOO호 | F7: 보통주 | G7: 1000000 | H7: =G7*$L$4 -> 100000000 | I7: =H7/$H$9 -> 0.066666667
A8: 4 | B8: 주식 | C8: =A8 -> 4 | D8: OO나 | E8: OO시 OOO구 OOOO2로 OO OOO동 OOOO호 | F8: 보통주 | G8: 330400 | H8: =G8*$L$4 -> 33040000 | I8: =H8/$H$9 -> 0.022026667
A9: 주주 지분권 합계 | G9: =SUM(G5:G8) -> 15000000 | H9: =SUM(H5:H8) -> 1500000000 | I9: =SUM(I5:I8) -> 1
D15: 김준연 | F15: 보통주 | H15: =G15*$L$4 -> 0 | I15: =H15/H16 -> #DIV/0!

Sheet 주주목록
A1: =A2 -> 11. 주주 지분권자의 목록
A2: 11. 주주 지분권자의 목록 | G2: 1~3행 반복
A4: 사건 | D4: =표지!$O$3&" "&표지!$O$4 -> 20○○회합100○○○ 회생 | E4: 채무자 | F4: =표지!$O$5 -> ○○○○ 주식회사
A5: 목록번호 | D5: 1 | E5: 신고번호 | G5: 5~9행부터 내리기
A6: 주주 지분권자 | B6: 성명·명칭 | D6: =VLOOKUP(D5,주주총괄!$A$5:$J$8,4,0) -> OO광
B7: 주소 | D7: =VLOOKUP(D5,주주총괄!$A$5:$J$8,5,0) -> OO도 OOO시 OO읍 OO로OOO번길 OO OO아파트 OOO동 OOO호
B8: 전화번호 | E8: e-mail
A9: 주식·출자지분의 종류와 수·액수 | B9: =VLOOKUP(D5,주주총괄!$A$5:$J$8,6,0) -> 보통주 | C9: =VLOOKUP(D5,주주총괄!$A$5:$J$8,7,0) -> 7442400 | D9: =VLOOKUP(D5,주주총괄!$A$5:$J$8,8,0) -> 744240000 | E9: ="(액면가액: "&TEXT(주주총괄!$L$4,"###,###원)") -> (액면가액: 100원)
A10: 비고
A11: 11. 주주 지분권자의 목록 | G11: 1~3행 반복
A13: 사건 | D13: =표지!$O$3&" "&표지!$O$4 -> 20○○회합100○○○ 회생 | E13: 채무자 | F13: =표지!$O$5 -> ○○○○ 주식회사
A14: 목록번호 | D14: 2 | E14: 신고번호 | G14: 5~9행부터 내리기
A15: 주주 지분권자 | B15: 성명·명칭 | D15: =VLOOKUP(D14,주주총괄!$A$5:$J$8,4,0) -> OO영
B16: 주소 | D16: =VLOOKUP(D14,주주총괄!$A$5:$J$8,5,0) -> OO시 OO구 OOOO2로 OO OOO동 OOOO호
B17: 전화번호 | E17: e-mail
A18: 주식·출자지분의 종류와 수·액수 | B18: =VLOOKUP(D14,주주총괄!$A$5:$J$8,6,0) -> 보통주 | C18: =VLOOKUP(D14,주주총괄!$A$5:$J$8,7,0) -> 6227200 | D18: =VLOOKUP(D14,주주총괄!$A$5:$J$8,8,0) -> 622720000 | E18: ="(액면가액: "&TEXT(주주총괄!$L$4,"###,###원)") -> (액면가액: 100원)
A19: 비고
A20: 11. 주주 지분권자의 목록 | G20: 1~3행 반복
A22: 사건 | D22: =표지!$O$3&" "&표지!$O$4 -> 20○○회합100○○○ 회생 | E22: 채무자 | F22: =표지!$O$5 -> ○○○○ 주식회사
A23: 목록번호 | D23: 3 | E23: 신고번호 | G23: 5~9행부터 내리기
A24: 주주 지분권자 | B24: 성명·명칭 | D24: =VLOOKUP(D23,주주총괄!$A$5:$J$8,4,0) -> OO훈
B25: 주소 | D25: =VLOOKUP(D23,주주총괄!$A$5:$J$8,5,0) -> 경기 OO시 OO읍 OO로 OOO, OOO동 OOOO호
B26: 전화번호 | E26: e-mail
A27: 주식·출자지분의 종류와 수·액수 | B27: =VLOOKUP(D23,주주총괄!$A$5:$J$8,6,0) -> 보통주 | C27: =VLOOKUP(D23,주주총괄!$A$5:$J$8,7,0) -> 1000000 | D27: =VLOOKUP(D23,주주총괄!$A$5:$J$8,8,0) -> 100000000 | E27: ="(액면가액: "&TEXT(주주총괄!$L$4,"###,###원)") -> (액면가액: 100원)
A28: 비고
A29: 11. 주주 지분권자의 목록
A31: 사건 | D31: =표지!$O$3&" "&표지!$O$4 -> 20○○회합100○○○ 회생 | E31: 채무자 | F31: =표지!$O$5 -> ○○○○ 주식회사
A32: 목록번호 | D32: 4 | E32: 신고번호
A33: 주주 지분권자 | B33: 성명·명칭 | D33: =VLOOKUP(D32,주주총괄!$A$5:$J$8,4,0) -> OO나
B34: 주소 | D34: =VLOOKUP(D32,주주총괄!$A$5:$J$8,5,0) -> OO시 OOO구 OOOO2로 OO OOO동 OOOO호
B35: 전화번호 | E35: e-mail
A36: 주식·출자지분의 종류와 수·액수 | B36: =VLOOKUP(D32,주주총괄!$A$5:$J$8,6,0) -> 보통주 | C36: =VLOOKUP(D32,주주총괄!$A$5:$J$8,7,0) -> 330400 | D36: =VLOOKUP(D32,주주총괄!$A$5:$J$8,8,0) -> 33040000 | E36: ="(액면가액: "&TEXT(주주총괄!$L$4,"###,###원)") -> (액면가액: 100원)
A37: 비고
A38: 11. 주주 지분권자의 목록
A40: 사건 | D40: =표지!$O$3&" "&표지!$O$4 -> 20○○회합100○○○ 회생 | E40: 채무자 | F40: =표지!$O$5 -> ○○○○ 주식회사
A41: 목록번호 | D41: 5 | E41: 신고번호
A42: 주주 지분권자 | B42: 성명·명칭 | D42: =VLOOKUP(D41,주주총괄!$A$5:$J$8,4,0) -> #N/A
B43: 주소 | D43: =VLOOKUP(D41,주주총괄!$A$5:$J$8,5,0) -> #N/A
B44: 전화번호 | E44: e-mail
A45: 주식·출자지분의 종류와 수·액수 | B45: =VLOOKUP(D41,주주총괄!$A$5:$J$8,6,0) -> #N/A | C45: =VLOOKUP(D41,주주총괄!$A$5:$J$8,7,0) -> #N/A | D45: =VLOOKUP(D41,주주총괄!$A$5:$J$8,8,0) -> #N/A | E45: ="(액면가액: "&TEXT(주주총괄!$L$4,"###,###원)") -> (액면가액: 100원)
...
