Workbook
Name 기업기업: '2-1.자금수지표(총괄)'!#REF!
Name 기업은행: '2-1.자금수지표(총괄)'!#REF!
Name 입금실적: '5.허가사항 내역'!#REF!
Name 입금실적: '3,4 어음수표 및 주요 업무사항'!#REF!
Name 입금실적: '3,4 어음수표 및 주요 업무사항'!#REF!
Name 입금실적: '3,4 어음수표 및 주요 업무사항'!#REF!
Name 입금실적: '3,4 어음수표 및 주요 업무사항'!#REF!
Name 입금실적: '3,4 어음수표 및 주요 업무사항'!#REF!
Name 통장: '2-1.자금수지표(총괄)'!#REF!
Name 통장: '2-1.자금수지표(총괄)'!#REF!
Name 통장: '2-1.자금수지표(총괄)'!#REF!
Name 통장: '2-1.자금수지표(총괄)'!#REF!
Name 통장: '2-1.자금수지표(총괄)'!#REF!
Name 통장: '2-1.자금수지표(총괄)'!#REF!
Name 허가사항내역: '2-1.자금수지표(총괄)'!#REF!
Name 허가사항내역: '2-1.자금수지표(총괄)'!#REF!
Name 허가사항내역: '2-1.자금수지표(총괄)'!#REF!
Name 허가사항내역: '2-1.자금수지표(총괄)'!#REF!
Name 허가사항내역: '2-1.자금수지표(총괄)'!#REF!
Name 현금: '2-1.자금수지표(총괄)'!#REF!
Name 현금: '2-1.자금수지표(총괄)'!#REF!
Name 현금: '2-1.자금수지표(총괄)'!#REF!
Name 현금: '2-1.자금수지표(총괄)'!#REF!
Name 현금: '2-1.자금수지표(총괄)'!#REF!
Name 현금: '2-1.자금수지표(총괄)'!#REF!

Sheet 표지
B2: 서울회생법원 제**부(나) | H2: 법원용
B3: 20** 간회합100*** 간이회생
B4: 20**. **. **. 회생절차 개시결정
B5: 20**. **. **. 회생계획 인가결정
B6: 월간보고서 (20**. 04.)
B9: 채무자 ㈜****** 법률상관리인 사내이사 * * *

Sheet 목차
A1: 1. 매출실적 및 입금실적 | B1: 1
A2: 2. 자금수지표(총괄)
A3: 2-1. 자금수지표(총괄) | B3: 2
A4: 2-2. 자금수지 실적명세표 | B4: 3
A5: 3. 어음 · 수표 발행현황(해당없음)
A6: 3-1. 어음 발행현황 | B6: 4
A7: 3-2. 수표 발행현황 | B7: 4
A8: 3-3. 당월 말 잔액의 월별 만기도래액 | B8: 4
A9: 4. 주요 업무사항
A10: 4-1. 매출실적 현황 | B10: 4~5
A11: 4-2. 입금실적 현황 | B11: 5
A12: 4-3. 회생절차진행 | B12: 5
A13: 5. 허가사항 내역
A14: 5-1. 허가사항 총괄표 | B14: 6
A15: 5-2. 법원허가사항 명세 | B15: 6
A16: 5-3. 관리위원 허가사항 명세 | B16: 6
A17: 6. 금원지출 내역
A18: 6-1. 금원지출 총괄표 | B18: 7
A19: 6-2. 법원 허가사항 지출 | B19: 7
A20: 6-3. 관리위원 허가사항 지출 | B20: 7
A21: 6-4. 300만원 초과 지출 내역 | B21: 7
A22: 6-5. 300만원 이하 지출 내역 | B22: 8~14
A23: 7. 공익채권 현황표 | B23: 15
A24: 8. 시재보유 현황 | B24: 16
A25: 9. 첨부서류
A26: - 20**년 4월 통장 사본

Sheet 1. 매출실적과 입금실적(전체)
B1: 1. 매출실적과 입금실적 | W1: 월별 매출액 입금 현황
B2: (20**. 04. 01. ~ 20**. 04. 30.) | W2: 년월 | X2: 매출입급 합계 | Y2: 입급 합계 | Z2: 출금합계 | AA2: NH 5353-83 | AD2: NH 5360-63 | AG2: NH 8661-53 | AJ2: SHB | AM2: KB | AP2: HANA | AS2: IBK
M3: (단위 : 원) | AA3: 매출입금 | AB3: 예금이자 등 기타 | AC3: 출금 | AD3: 매출입금 | AE3: 예금이자 등 기타 | AF3: 출금 | AG3: 매출입금 | AH3: 예금이자 등 기타 | AI3: 출금 | AJ3: 매출입금 | AK3: 예금이자 등 기타 | AL3: 출금 | AM3: 매출입금 | AN3: 예금이자 등 기타 | AO3: 출금 | AP3: 매출입금 | AQ3: 예금이자 등 기타 | AR3: 출금 | AS3: 매출입금 | AT3: 예금이자 등 기타 | AU3: 출금
B4: 구 분 | D4: 매 출 실 적 | I4: 입 금 실 적 | Q4: 구분 | R4: 1차연도(2021년) | W4: 2019-1월 | X4: =AA4+AD4+AG4+AJ4+AM4+AP4+AS4 -> 212656140 | Y4: =AA4+AB4+AD4+AE4+AG4+AH4+AJ4+AK4+AM4+AN4+AP4+AQ4+AS4+AT4 -> 233987005 | Z4: =AC4+AF4+AI4+AL4+AO4+AR4+AU4 -> 235319933 | AD4: 0 | AE4: 0 | AF4: 0 | AG4: 0 | AH4: 0 | AI4: 0 | AJ4: 113493220 | AK4: 12700000 | AL4: 171512171 | AM4: 8079000 | AO4: 20011690 | AR4: 20 | AS4: 91083920 | AT4: 8630865 | AU4: 43796052
D5: 20**년 | E5: 20**년 | G5: 달성율 | I5: 20**년 | J5: 20**년 | L5: 달성율 | R5: 회생계획 | T5: 기초현금 | U5: =R17 -> 9277573 | W5: 2019-2월 | X5: =AA5+AD5+AG5+AJ5+AM5+AP5+AS5 -> 169118080 | Y5: =AA5+AB5+AD5+AE5+AG5+AH5+AJ5+AK5+AM5+AN5+AP5+AQ5+AS5+AT5 -> 175519881 | Z5: =AC5+AF5+AI5+AL5+AO5+AR5+AU5 -> 173814024 | AD5: 0 | AE5: 0 | AF5: 0 | AG5: 0 | AH5: 0 | AI5: 0 | AJ5: 154789950 | AK5: 6250000 | AL5: 152286333 | AO5: 11957760 | AS5: 14328130 | AT5: 151801 | AU5: 9569931
D6: 실적 | E6: 회생 계획 | F6: 실적 | G6: 전년 대비 | H6: 회생계획 대비 | I6: 실적 | J6: 회생 계획 | K6: 실적 | L6: 전년 실적 | M6: 회생계획 대비 | Q6: 매출액 | R6: 1663917476 | W6: 2019-3월 | X6: =AA6+AD6+AG6+AJ6+AM6+AP6+AS6 -> 155754465 | Y6: =AA6+AB6+AD6+AE6+AG6+AH6+AJ6+AK6+AM6+AN6+AP6+AQ6+AS6+AT6 -> 160280554 | Z6: =AC6+AF6+AI6+AL6+AO6+AR6+AU6 -> 156842865 | AD6: 0 | AE6: 0 | AF6: 0 | AG6: 0 | AH6: 0 | AI6: 0 | AJ6: 92432965 | AK6: 4000000 | AL6: 137225664 | AN6: 73 | AO6: 11427700 | AQ6: 15 | AR6: 32000 | AS6: 63321500 | AT6: 526001 | AU6: 8157501
Q7: 매출원가 | R7: 1520618605 | T7: 월 수입 | U7: =R6+R21+R27+R28+R20+R29 -> 1685272347 | W7: 2019-4월 | X7: =AA7+AD7+AG7+AJ7+AM7+AP7+AS7 -> 189600180 | Y7: =AA7+AB7+AD7+AE7+AG7+AH7+AJ7+AK7+AM7+AN7+AP7+AQ7+AS7+AT7 -> 200650180 | Z7: =AC7+AF7+AI7+AL7+AO7+AR7+AU7 -> 206048154 | AD7: 0 | AE7: 0 | AF7: 0 | AG7: 0 | AH7: 0 | AI7: 0 | AJ7: 84019170 | AK7: 11050000 | AL7: 192912204 | AM7: 8600000 | AO7: 1000900 | AR7: 40 | AS7: 96981010 | AU7: 12135010
B8: 1 | C8: 1월 | D8: 66443325 | E8: 30198320 | F8: 30198320 | G8: =F8/D8 -> 0.45449742 | H8: =F8/E8 -> 1 | I8: 98132973 | J8: 30198320 | K8: 23611690 | L8: =K8/I8 -> 0.24060914 | M8: =K8/J8 -> 0.78188754 | Q8: (매출원가율) | R8: =R7/R6 -> 0.91387862 | W8: 2019-5월 | X8: =AA8+AD8+AG8+AJ8+AM8+AP8+AS8 -> 217581573 | Y8: =AA8+AB8+AD8+AE8+AG8+AH8+AJ8+AK8+AM8+AN8+AP8+AQ8+AS8+AT8 -> 220779143 | Z8: =AC8+AF8+AI8+AL8+AO8+AR8+AU8 -> 219618797 | AD8: 0 | AE8: 0 | AF8: 0 | AG8: 0 | AH8: 0 | AI8: 0 | AJ8: 185583498 | AK8: 3189490 | AL8: 201368542 | AM8: 1123250 | AO8: 11949350 | AS8: 30874825 | AT8: 8080 | AU8: 6300905
C9: 2월 | D9: 100904816 | E9: =ROUND($R$6/11,0) -> 151265225 | F9: 36754325 | G9: =F9/D9 -> 0.36424748 | H9: =F9/E9 -> 0.24297934 | I9: 79494567 | J9: =ROUND($R$6/11,0) -> 151265225 | K9: 68530206 | L9: =K9/I9 -> 0.86207408 | M9: =K9/J9 -> 0.45304667 | Q9: 매출총이익 | R9: =R6-R7 -> 143298871 | T9: 월 지출 | U9: =R7+R11-R22-R23-R24-R26 -> 1645616988 | W9: 2019-6월 | X9: =AA9+AD9+AG9+AJ9+AM9+AP9+AS9 -> 150155557 | Y9: =AA9+AB9+AD9+AE9+AG9+AH9+AJ9+AK9+AM9+AN9+AP9+AQ9+AS9+AT9 -> 179060713 | Z9: =AC9+AF9+AI9+AL9+AO9+AR9+AU9 -> 165947203 | AA9: 84648000 | AB9: 181 | AC9: 83907590 | AD9: 0 | AE9: 0 | AF9: 0 | AG9: 0 | AH9: 0 | AI9: 0 | AJ9: 31110607 | AK9: 28702464 | AL9: 50301039 | AN9: 3 | AO9: 900 | AQ9: 8 | AS9: 34396950 | AT9: 202500 | AU9: 31737674
B10: / | C10: 3월 | D10: 139997112 | E10: =ROUND($R$6/11,0) -> 151265225 | F10: 132265225 | G10: =F10/D10 -> 0.9447711 | H10: =F10/E10 -> 0.87439281 | I10: 71367273 | J10: =ROUND($R$6/11,0) -> 151265225 | K10: 113474428 | L10: =K10/I10 -> 1.5900065 | M10: =K10/J10 -> 0.75016864 | Q10: (매출총이익율) | R10: =R9/R6 -> 0.086121381 | T10: 법인세비용 | U10: 0 | W10: 2019-7월 | X10: =AA10+AD10+AG10+AJ10+AM10+AP10+AS10 -> 258797709 | Y10: =AA10+AB10+AD10+AE10+AG10+AH10+AJ10+AK10+AM10+AN10+AP10+AQ10+AS10+AT10 -> 296290686 | Z10: =AC10+AF10+AI10+AL10+AO10+AR10+AU10 -> 304701635 | AA10: 249721570 | AB10: 37492710 | AC10: 304701615 | AD10: 0 | AE10: 0 | AF10: 0 | AG10: 0 | AH10: 0 | AI10: 0 | AJ10: 6183500 | AK10: 0 | AL10: 0 | AM10: 1116139 | AR10: 20 | AS10: 1776500 | AT10: 267 | AU10: 0
B11: 분 기 | C11: 소계 | D11: =SUM(D8:D10) -> 307345253 | E11: =SUM(E8:E10) -> 332728770 | F11: =SUM(F8:F10) -> 199217870 | G11: =F11/D11 -> 0.64818919 | H11: =F11/E11 -> 0.59873954 | I11: =SUM(I8:I10) -> 2.4899481e+08 | J11: =SUM(J8:J10) -> 332728770 | K11: =SUM(K8:K10) -> 205616324 | L11: =K11/I11 -> 0.82578557 | M11: =K11/J11 -> 0.61796978 | Q11: 판매비와 관리비 | R11: 124998383 | T11: 12월 지출 | U11: =R47 -> 1380200 | W11: 2019-8월 | X11: =AA11+AD11+AG11+AJ11+AM11+AP11+AS11 -> 142179480 | Y11: =AA11+AB11+AD11+AE11+AG11+AH11+AJ11+AK11+AM11+AN11+AP11+AQ11+AS11+AT11 -> 142179764 | Z11: =AC11+AF11+AI11+AL11+AO11+AR11+AU11 -> 147284049 | AA11: 141677600 | AC11: 124125469 | AD11: 0 | AE11: 0 | AF11: 0 | AG11: 0 | AH11: 0 | AI11: 0 | AJ11: 0 | AK11: 0 | AL11: 18258236 | AS11: 501880 | AT11: 284 | AU11: 4900344
B12: 2 | C12: 4월 | D12: 53143810 | E12: =ROUND($R$6/11,0) -> 151265225 | F12: 114485701 | G12: =F12/D12 -> 2.1542622 | H12: =F12/E12 -> 0.75685407 | I12: 1.2955484e+08 | J12: =ROUND($R$6/11,0) -> 151265225 | K12: 206221820 | L12: =K12/I12 -> 1.5917724 | M12: =K12/J12 -> 1.3633128 | Q12: (판매관리비율) | R12: =R11/R6 -> 0.075122946 | W12: 2019-9월 | X12: =AA12+AD12+AG12+AJ12+AM12+AP12+AS12 -> 136663444 | Y12: =AA12+AB12+AD12+AE12+AG12+AH12+AJ12+AK12+AM12+AN12+AP12+AQ12+AS12+AT12 -> 145904005 | Z12: =AC12+AF12+AI12+AL12+AO12+AR12+AU12 -> 146829836 | AA12: 129054564 | AB12: 9240452 | AC12: 142365266 | AD12: 0 | AE12: 0 | AF12: 0 | AG12: 0 | AH12: 0 | AI12: 0 | AJ12: 1848880 | AK12: 0 | AL12: 1751500 | AN12: 1 | AQ12: 8 | AS12: 5760000 | AT12: 100 | AU12: 2713070
B13: / | C13: 5월 | D13: 82379091 | E13: =ROUND($R$6/11,0) -> 151265225 | G13: =F13/D13 -> 0 | H13: =F13/E13 -> 0 | I13: 93603228 | J13: =ROUND($R$6/11,0) -> 151265225 | L13: =K13/I13 -> 0 | M13: =K13/J13 -> 0 | Q13: 영업이익 | R13: =R9-R11 -> 18300488 | T13: 이월잔액 | U13: =U5+U7-U9-U11-U10 -> 47552732 | W13: 2019-10월 | X13: =AA13+AD13+AG13+AJ13+AM13+AP13+AS13 -> 228469584 | Y13: =AA13+AB13+AD13+AE13+AG13+AH13+AJ13+AK13+AM13+AN13+AP13+AQ13+AS13+AT13 -> 241284464 | Z13: =AC13+AF13+AI13+AL13+AO13+AR13+AU13 -> 237237850 | AA13: 180580584 | AB13: 2746605 | AC13: 179848191 | AD13: 0 | AE13: 0 | AF13: 0 | AG13: 0 | AH13: 0 | AI13: 0 | AJ13: 43176000 | AK13: 9300000 | AL13: 52402880 | AO13: 2352840 | AR13: 30500 | AS13: 4713000 | AT13: 768275 | AU13: 2603439
B14: 4 | C14: 6월 | D14: 136754019 | E14: =ROUND($R$6/11,0) -> 151265225 | G14: =F14/D14 -> 0 | H14: =F14/E14 -> 0 | I14: 1.0148287e+08 | J14: =ROUND($R$6/11,0) -> 151265225 | L14: =K14/I14 -> 0 | M14: =K14/J14 -> 0 | T14: 차액 | U14: =U13-R48 -> 0 | W14: 2019-11월 | X14: =AA14+AD14+AG14+AJ14+AM14+AP14+AS14 -> 116123770 | Y14: =AA14+AB14+AD14+AE14+AG14+AH14+AJ14+AK14+AM14+AN14+AP14+AQ14+AS14+AT14 -> 161928512 | Z14: =AC14+AF14+AI14+AL14+AO14+AR14+AU14 -> 150001372 | AA14: 107998520 | AB14: 45804740 | AC14: 142380924 | AD14: 0 | AE14: 0 | AF14: 0 | AG14: 0 | AH14: 0 | AI14: 0 | AJ14: 4700000 | AL14: 4700000 | AO14: 2185276 | AR14: 20 | AS14: 3425250 | AT14: 2 | AU14: 735152
B15: 분 기 | C15: 소계 | D15: =SUM(D12:D14) -> 272276920 | E15: =SUM(E12:E14) -> 453795675 | F15: =SUM(F12:F14) -> 114485701 | G15: =F15/D15 -> 0.42047523 | H15: =F15/E15 -> 0.25228469 | I15: =SUM(I12:I14) -> 3.2464094e+08 | J15: =SUM(J12:J14) -> 453795675 | K15: =SUM(K12:K14) -> 206221820 | L15: =K15/I15 -> 0.63523049 | M15: =K15/J15 -> 0.45443761 | P15: 구분 | R15: 1차연도 | W15: 2019-12월 | X15: =AA15+AD15+AG15+AJ15+AM15+AP15+AS15 -> 169189420 | Y15: =AA15+AB15+AD15+AE15+AG15+AH15+AJ15+AK15+AM15+AN15+AP15+AQ15+AS15+AT15 -> 172844655 | Z15: =AC15+AF15+AI15+AL15+AO15+AR15+AU15 -> 185346552 | AA15: 168474220 | AB15: 2539276 | AC15: 183515419 | AD15: 0 | AE15: 0 | AF15: 0 | AG15: 0 | AH15: 0 | AI15: 0 | AK15: 1113118 | AL15: 1113118 | AM15: 331500 | AN15: 15 | AO15: 330515 | AQ15: 2 | AS15: 383700 | AT15: 2824 | AU15: 387500
B16: 3 | C16: 7월 | D16: 115637750 | E16: =ROUND($R$6/11,0) -> 151265225 | G16: =F16/D16 -> 0 | H16: =F16/E16 -> 0 | I16: 1.3407908e+08 | J16: =ROUND($R$6/11,0) -> 151265225 | L16: =K16/I16 -> 0 | M16: =K16/J16 -> 0 | O16: =K16='2-2.자금수지 실적 명세표'!C12 -> FALSE | R16: 2021년 | W16: 2020-1월 | X16: =AA16+AD16+AG16+AJ16+AM16+AP16+AS16 -> 107946270 | Y16: =AA16+AB16+AD16+AE16+AG16+AH16+AJ16+AK16+AM16+AN16+AP16+AQ16+AS16+AT16 -> 112806596 | Z16: =AC16+AF16+AI16+AL16+AO16+AR16+AU16 -> 112766959 | AA16: 104438620 | AB16: 4860326 | AC16: 109262089 | AG16: 0 | AH16: 0 | AI16: 0 | AJ16: 64350 | AL16: 64350 | AR16: 20 | AS16: 3443300 | AU16: 3440500
B17: / | C17: 8월 | D17: 179684041 | E17: =ROUND($R$6/11,0) -> 151265225 | G17: =F17/D17 -> 0 | H17: =F17/E17 -> 0 | I17: 1.4635937e+08 | J17: =ROUND($R$6/11,0) -> 151265225 | L17: =K17/I17 -> 0 | M17: =K17/J17 -> 0 | P17: Ⅰ.자금의 원천 | Q17: 기초의 현금 | R17: 9277573 | W17: 2020-2월 | X17: =AA17+AD17+AG17+AJ17+AM17+AP17+AS17 -> 87444024 | Y17: =AA17+AB17+AD17+AE17+AG17+AH17+AJ17+AK17+AM17+AN17+AP17+AQ17+AS17+AT17 -> 103428474 | Z17: =AC17+AF17+AI17+AL17+AO17+AR17+AU17 -> 76629038 | AA17: 65241824 | AB17: 15982682 | AC17: 58236738 | AD17: 18982200 | AE17: 1000 | AF17: 18392300 | AG17: 0 | AH17: 0 | AI17: 0 | AJ17: 3000000 | AK17: 760 | AS17: 220000 | AT17: 8
B18: 4 | C18: 9월 | D18: 61319455 | E18: =ROUND($R$6/11,0) -> 151265225 | G18: =F18/D18 -> 0 | H18: =F18/E18 -> 0 | I18: 1.3702827e+08 | J18: =ROUND($R$6/11,0) -> 151265225 | L18: =K18/I18 -> 0 | M18: =K18/J18 -> 0 | Q18: 영업활동으로인한현금흐름 | R18: =SUM(R19:R24) -> 39655359 | W18: 2020-3월 | X18: =AA18+AD18+AG18+AJ18+AM18+AP18+AS18 -> 78504000 | Y18: =AA18+AB18+AD18+AE18+AG18+AH18+AJ18+AK18+AM18+AN18+AP18+AQ18+AS18+AT18 -> 81321890 | Z18: =AC18+AF18+AI18+AL18+AO18+AR18+AU18 -> 102518320 | AA18: 8167500 | AB18: 531 | AC18: =25751333+4730000 -> 30481333 | AD18: 68686500 | AE18: 2817342 | AF18: 72036987 | AG18: 0 | AH18: 0 | AI18: 0 | AJ18: 220000 | AS18: 1430000 | AT18: 17
B19: 분 기 | C19: 소계 | D19: =SUM(D16:D18) -> 356641246 | E19: =SUM(E16:E18) -> 453795675 | F19: =SUM(F16:F18) -> 0 | G19: =F19/D19 -> 0 | H19: =F19/E19 -> 0 | I19: =SUM(I16:I18) -> 4.1746672e+08 | J19: =SUM(J16:J18) -> 453795675 | K19: =SUM(K16:K18) -> 0 | L19: =K19/I19 -> 0 | M19: =K19/J19 -> 0 | Q19: 세후영업이익 | R19: =R13 -> 18300488 | W19: 2020-4월 | X19: =AA19+AD19+AG19+AJ19+AM19+AP19+AS19 -> 142510325 | Y19: =AA19+AB19+AD19+AE19+AG19+AH19+AJ19+AK19+AM19+AN19+AP19+AQ19+AS19+AT19 -> 146591569 | Z19: =AC19+AF19+AI19+AL19+AO19+AR19+AU19 -> 142987856 | AA19: 2227500 | AD19: 139632825 | AE19: 4080000 | AF19: 142987856 | AG19: 0 | AH19: 1121 | AS19: 650000 | AT19: 123
B20: 4 | C20: 10월 | D20: 85080036 | E20: =ROUND($R$6/11,0) -> 151265225 | G20: =F20/D20 -> 0 | H20: =F20/E20 -> 0 | I20: 50082231 | J20: =ROUND($R$6/11,0) -> 151265225 | L20: =K20/I20 -> 0 | M20: =K20/J20 -> 0 | Q20: 운전자금변동 | R20: 19469131 | W20: 2020-5월 | X20: =AA20+AD20+AG20+AJ20+AM20+AP20+AS20 -> 102963551 | Y20: =AA20+AB20+AD20+AE20+AG20+AH20+AJ20+AK20+AM20+AN20+AP20+AQ20+AS20+AT20 -> 107693726 | Z20: =AC20+AF20+AI20+AL20+AO20+AR20+AU20 -> 105294314 | AA20: 2707375 | AD20: 99900876 | AE20: 4730000 | AF20: 105294314 | AG20: 0 | AH20: 0 | AI20: 0 | AS20: 355300 | AT20: 175
B21: / | C21: 11월 | D21: 27560500 | E21: =ROUND($R$6/11,0) -> 151265225 | G21: =F21/D21 -> 0 | H21: =F21/E21 -> 0 | I21: 82218820 | J21: =ROUND($R$6/11,0) -> 151265225 | L21: =K21/I21 -> 0 | M21: =K21/J21 -> 0 | Q21: 감가상각비(유무형) | R21: 1885740 | W21: 2020-6월 | X21: =AA21+AD21+AG21+AJ21+AM21+AP21+AS21 -> 111631154 | Y21: =AA21+AB21+AD21+AE21+AG21+AH21+AJ21+AK21+AM21+AN21+AP21+AQ21+AS21+AT21 -> 118471113 | Z21: =AC21+AF21+AI21+AL21+AO21+AR21+AU21 -> 113849547 | AA21: 2792349 | AB21: 910 | AD21: 107122805 | AE21: 6838795 | AF21: 113849547 | AG21: 0 | AH21: 0 | AI21: 0 | AS21: 1716000 | AT21: 254
B22: 4 | C22: 12월 | D22: 87960273 | E22: =ROUND($R$6/11,0) -> 151265225 | G22: =F22/D22 -> 0 | H22: =F22/E22 -> 0 | I22: 41873112 | J22: =ROUND($R$6/11,0) -> 151265225 | L22: =K22/I22 -> 0 | M22: =K22/J22 -> 0 | Q22: 순운전자본증감액 | R22: 0 | W22: 2020-7월 | X22: =AA22+AD22+AG22+AJ22+AM22+AP22+AS22 -> 147486990 | Y22: =AA22+AB22+AD22+AE22+AG22+AH22+AJ22+AK22+AM22+AN22+AP22+AQ22+AS22+AT22 -> 162388387 | Z22: =AC22+AF22+AI22+AL22+AO22+AR22+AU22 -> 156747511 | AA22: 907500 | AD22: 146579490 | AE22: 9820000 | AF22: 151667211 | AG22: 0 | AH22: 5081100 | AI22: 5080300 | AT22: 297
B23: 분 기 | C23: 소계 | D23: =SUM(D20:D22) -> 200600809 | E23: =SUM(E20:E22) -> 453795675 | F23: =SUM(F20:F22) -> 0 | G23: =F23/D23 -> 0 | H23: =F23/E23 -> 0 | I23: =SUM(I20:I22) -> 1.7417416e+08 | J23: =SUM(J20:J22) -> 453795675 | K23: =SUM(K20:K22) -> 0 | L23: =K23/I23 -> 0 | M23: =K23/J23 -> 0 | Q23: 퇴직금지급액 | W23: 2020-8월 | X23: =AA23+AD23+AG23+AJ23+AM23+AP23+AS23 -> 160995305 | Y23: =AA23+AB23+AD23+AE23+AG23+AH23+AJ23+AK23+AM23+AN23+AP23+AQ23+AS23+AT23 -> 160995640 | Z23: =AC23+AF23+AI23+AL23+AO23+AR23+AU23 -> 133604291 | AD23: 160995305 | AF23: 133604291 | AG23: 0 | AH23: 0 | AI23: 0 | AT23: 335
B24: 그달까지의 누계 | D24: =D11+D12 -> 360489063 | E24: =E11+E12 -> 483993995 | F24: =F11+F15+F19+F23 -> 313703571 | G24: =F24/D24 -> 0.87021661 | H24: =F24/E24 -> 0.64815592 | I24: =I11+I12 -> 3.7854965e+08 | J24: =J11+J12 -> 483993995 | K24: =K11+K15+K19+K23 -> 411838144 | L24: =K24/I24 -> 1.0879369 | M24: =K24/J24 -> 0.85091581 | Q24: 임차보증금 감소 | R24: 0 | W24: 2020-9월 | X24: =AA24+AD24+AG24+AJ24+AM24+AP24+AS24 -> 0 | Y24: =AA24+AB24+AD24+AE24+AG24+AH24+AJ24+AK24+AM24+AN24+AP24+AQ24+AS24+AT24 -> 0 | Z24: =AC24+AF24+AI24+AL24+AO24+AR24+AU24 -> 0
B25: 합계 | D25: =SUM(D23,D19,D15,D11) -> 1136864228 | E25: =SUM(E23,E19,E15,E11) -> 1694115795 | F25: =SUM(F23,F19,F15,F11) -> 313703571 | G25: =F25/D25 -> 0.27593759 | H25: =F25/E25 -> 0.18517245 | I25: =SUM(I23,I19,I15,I11) -> 1.1652766e+09 | J25: =SUM(J23,J19,J15,J11) -> 1694115795 | K25: =SUM(K23,K19,K15,K11) -> 411838144 | L25: =K25/I25 -> 0.35342521 | M25: =K25/J25 -> 0.24309917 | Q25: 투자활동으로인한현금흐름 | R25: =SUM(R26:R29) -> 0 | W25: 2020-10월 | X25: =AA25+AD25+AG25+AJ25+AM25+AP25+AS25 -> 0 | Y25: =AA25+AB25+AD25+AE25+AG25+AH25+AJ25+AK25+AM25+AN25+AP25+AQ25+AS25+AT25 -> 0 | Z25: =AC25+AF25+AI25+AL25+AO25+AR25+AU25 -> 0 | AF25: 0 | AG25: 0 | AH25: 0 | AI25: 0
Q26: 유형자산재투자 | R26: 0 | W26: 2020-11월 | X26: =AA26+AD26+AG26+AJ26+AM26+AP26+AS26 -> 0 | Y26: =AA26+AB26+AD26+AE26+AG26+AH26+AJ26+AK26+AM26+AN26+AP26+AQ26+AS26+AT26 -> 0 | Z26: =AC26+AF26+AI26+AL26+AO26+AR26+AU26 -> 0 | AF26: 0 | AG26: 0 | AH26: 0 | AI26: 0
B27: (註)1. 부가가치세는 매출실적 및 입금실적에서 제외할 것["자금수지표(총괄)와 상이한 점에 유의할 것] 2. 받을어음은 입금실적에서 제외할 것(실제 입금시 반영) 3. 달성율은 전년 및 회생계획과 대비한 실적의 비율을 %로 기재(예컨대, 10% 초과 달성한 경우에는 110%, 10%미달한 경우에는 90%로 기재. / 이하에서 '달성률'이라고 표현한 것은 이와 마찬가지로 표기하고, '증감률'이라고 표현한 것은 +10%, -10%식으로 기재하고, 단순히 '증감'이라고 표현한 것은 그 차액을 기재) 4. 그 달까지의 누계는 당월까지의 실적∙회생계획의 누계와 그 달성률을 표기할 것. | Q27: 본사(공장토지건물) 처분 | R27: 0 | W27: 2020-12월 | X27: =AA27+AD27+AG27+AJ27+AM27+AP27+AS27 -> 0 | Y27: =AA27+AB27+AD27+AE27+AG27+AH27+AJ27+AK27+AM27+AN27+AP27+AQ27+AS27+AT27 -> 0 | Z27: =AC27+AF27+AI27+AL27+AO27+AR27+AU27 -> 0 | AF27: 0 | AG27: 0 | AI27: 0
Q28: 단기금융상품회수 | R28: 0 | W28: Total | X28: =SUM(X4:X27) -> 3085771021 | Y28: =SUM(Y4:Y27) -> 3324406957 | Z28: =SUM(Z4:Z27) -> 3273390106 | AA28: =SUM(AA4:AA27) -> 1248637726 | AB28: =SUM(AB4:AB27) -> 118668413 | AC28: =SUM(AC4:AC27) -> 1358824634 | AD28: =SUM(AD4:AD27) -> 741900001 | AE28: =SUM(AE4:AE27) -> 28287137 | ... AU28: =SUM(AU4:AU27) -> 126477078
Q29: 임차보증금의 지급 | R29: 0
Q30: 재무활동으로인한현금흐름 | R30: 0
P31: 자금의 원천 합계 | R31: =R17+R18+R25+R30 -> 48932932
P32: Ⅱ.자금의 운용 | Q32: 1. 회생담보권 | R32: =SUM(R33:R35) -> 0
Q33: 대여금채권
Q34: 원금 및 개시전이자 | R34: 0
Q35: 개시후이자 | R35: 0
Q36: 2. 회생채권 | R36: =SUM(R37:R43) -> 0
Q37: 대여금채권
Q38: 구상채권
Q39: 상거래채권
Q40: 소액상거래채권
...

Sheet 2-1.자금수지표(총괄)
A1: 2. 자금수지표(총괄)
A2: 2-1. 자금수지표(총괄)
A3: ='1. 매출실적과 입금실적(전체)'!B2 -> (20**. 04. 01. ~ 20**. 04. 30.) | O3: 부동산처분금액(12월) | P3: 차액
I4: (단위 : 원) | M4: 기초현금 | N4: ='1. 매출실적과 입금실적(전체)'!U5 -> 9277573
A5: 구분 | C5: 회생계획 | F5: 실 적 | I5: 달성율(%) | J5: 비고 | M5: 월 수입 | N5: ='1. 매출실적과 입금실적(전체)'!U7 -> 1685272347 | O5: 0 | P5: =N5-O5 -> 1685272347
A6: 분기 | B6: 월 | C6: 수입 | D6: 지출 | E6: 이월잔액 (자금수지) | F6: 수입 | G6: 지출 | H6: 이월잔액 (자금수지) | M6: 월 지출 | N6: ='1. 매출실적과 입금실적(전체)'!U9+'1. 매출실적과 입금실적(전체)'!U10 -> 1645616988 | O6: 0 | P6: =N6-O6 -> 1645616988
A7: 전기이월잔액 | E7: 24095570 | H7: 24095570 | I7: =H7/E7 -> 1 | M7: 12월 지출 | N7: ='1. 매출실적과 입금실적(전체)'!U11 -> 1380200 | O7: 0 | P7: =N7-O7 -> 1380200
A8: 1 | B8: 1 | C8: 23652690 | D8: 43136587 | E8: =E7+C8-D8 -> 4611673 | F8: 23652690 | G8: 43136587 | H8: =H7+F8-G8 -> 4611673 | I8: =H8/E8 -> 1 | M8: 이월잔액 | N8: ='1. 매출실적과 입금실적(전체)'!U13 -> 47552732
A9: / | B9: 2 | C9: =ROUND($P$5/11,0) -> 153206577 | D9: =ROUND(($N$6+$P$7)/11,0) -> 149727017 | E9: =E8+C9-D9 -> 8091233 | F9: 72950038 | G9: 25144841 | H9: =H8+F9-G9 -> 52416870 | I9: =H9/E9 -> 6.4782302
A10: 4 | B10: 3 | C10: =ROUND($P$5/11,0) -> 153206577 | D10: =ROUND(($N$6+$P$7)/11,0) -> 149727017 | E10: =E9+C10-D10 -> 11570793 | F10: 113955896 | G10: 129363277 | H10: =H9+F10-G10 -> 37009489 | I10: =H10/E10 -> 3.1985266
A11: 분기 | B11: 소계 | C11: =SUM(C8:C10) -> 330065844 | D11: =SUM(D8:D10) -> 342590621 | E11: =C11-D11 -> -12524777 | F11: =SUM(F8:F10) -> 210558624 | G11: =SUM(G8:G10) -> 197644705 | H11: =H7+F11-G11 -> 37009489
A12: 2 | B12: 4 | C12: =ROUND($P$5/11,0) -> 153206577 | D12: =ROUND(($N$6+$P$7)/11,0) -> 149727017 | E12: =E10+C12-D12 -> 15050353 | F12: 213985911 | G12: 90248573 | H12: =SUM(H10+F12-G12) -> 160746827 | I12: =H12/E12 -> 10.680602
A13: / | B13: 5 | C13: =ROUND($P$5/11,0) -> 153206577 | D13: =ROUND(($N$6+$P$7)/11,0) -> 149727017 | E13: =E12+C13-D13 -> 18529913 | H13: =SUM(H12+F13-G13) -> 160746827 | I13: =H13/E13 -> 8.6749909
A14: 4 | B14: 6 | C14: =ROUND($P$5/11,0) -> 153206577 | D14: =ROUND(($N$6+$P$7)/11,0) -> 149727017 | E14: =E13+C14-D14 -> 22009473 | H14: =SUM(H13+F14-G14) -> 160746827 | I14: =H14/E14 -> 7.3035291
A15: 분기 | B15: 소계 | C15: =SUM(C12:C14) -> 459619731 | D15: =SUM(D12:D14) -> 449181051 | E15: =C15-D15 -> 10438680 | F15: =SUM(F12:F14) -> 213985911 | G15: =SUM(G12:G14) -> 90248573 | H15: =H11+F15-G15 -> 160746827 | M15: 112970066 | N15: 74009724
A16: 3 | B16: 7 | C16: =ROUND($P$5/11,0) -> 153206577 | D16: =ROUND(($N$6+$P$7)/11,0) -> 149727017 | E16: =E14+C16-D16 -> 25489033 | H16: =H14+F16-G16 -> 160746827 | I16: =H16/E16 -> 6.3065094
A17: / | B17: 8 | C17: =ROUND($P$5/11,0) -> 153206577 | D17: =ROUND(($N$6+$P$7)/11,0) -> 149727017 | E17: =E16+C17-D17 -> 28968593 | H17: =H16+F17-G17 -> 160746827 | I17: =H17/E17 -> 5.5490036 | M17: 112970066 | N17: 74009724
A18: 4 | B18: 9 | C18: =ROUND($P$5/11,0) -> 153206577 | D18: =ROUND(($N$6+$P$7)/11,0) -> 149727017 | E18: =E17+C18-D18 -> 32448153 | H18: =H17+F18-G18 -> 160746827 | I18: =H18/E18 -> 4.9539592 | L18: =H18='2-2.자금수지 실적 명세표'!C55 -> TRUE | O18: 141278594
A19: 분기 | B19: 소계 | C19: =SUM(C16:C18) -> 459619731 | D19: =SUM(D16:D18) -> 449181051 | E19: =C19-D19 -> 10438680 | F19: =SUM(F16:F18) -> 0 | G19: =SUM(G16:G18) -> 0 | H19: =H15+F19-G19 -> 160746827 | K19: =H17-24843371 -> 135903456 | L19: =H16='8.시재현황'!D18 -> FALSE | O19: 180238936
A20: 4 | B20: 10 | C20: =ROUND($P$5/11,0) -> 153206577 | D20: =ROUND(($N$6+$P$7)/11,0) -> 149727017 | E20: =E18+C20-D20 -> 35927713 | H20: =H18+F20-G20 -> 160746827 | I20: =H20/E20 -> 4.4741737
A21: / | B21: 11 | C21: =ROUND($P$5/11,0) -> 153206577 | D21: =ROUND(($N$6+$P$7)/11,0) -> 149727017 | E21: =E20+C21-D21 -> 39407273 | H21: =H20+F21-G21 -> 160746827 | I21: =H21/E21 -> 4.0791157 | O21: 38960342
A22: 4 | B22: 12 | C22: =ROUND($P$5/11,0) -> 153206577 | D22: =ROUND(($N$6+$P$7)/11,0) -> 149727017 | E22: =E21+C22-D22 -> 42886833 | H22: =H21+F22-G22 -> 160746827 | I22: =H22/E22 -> 3.7481627 | K22: =H22='8.시재현황'!D18 -> FALSE | M22: =H8-#REF! -> #REF!
A23: 분기 | B23: 소계 | C23: =SUM(C20:C22) -> 459619731 | D23: =SUM(D20:D22) -> 449181051 | E23: =C23-D23 -> 10438680 | F23: =SUM(F20:F22) -> 0 | G23: =SUM(G20:G22) -> 0 | H23: =H19+F23-G23 -> 160746827 | M23: ='8.시재현황'!D9+'8.시재현황'!#REF! -> #REF!
A24: 그달까지의 누계 | C24: =C11+C12 -> 483272421 | D24: =D11+D12 -> 492317638 | E24: =E7+C24-D24 -> 15050353 | F24: =F11+F15+F19+F23 -> 424544535 | G24: =G11+G15+G19+G23 -> 287893278 | H24: =H7+F24-G24 -> 160746827 | I24: =H24/E24 -> 10.680602
A25: 합계 | C25: =C11+C15+C19+C23 -> 1708925037 | D25: =D11+D15+D19+D23 -> 1690133774 | E25: =E7+C25-D25 -> 42886833 | F25: =F11+F15+F19+F23 -> 424544535 | G25: =G11+G15+G19+G23 -> 287893278 | H25: =H7+F25-G25 -> 160746827 | I25: =H25/E25 -> 3.7481627 | M25: =H8-M23 -> #REF!
A26: ='8.시재현황'!A19 -> (註) 시재보유 금액 \202,137,563원중 공탁금 및 퇴직연금 잔액 \41,390,736원을 제외한 실제 가용자금은 \160,746,827원입니다.
A27: 1. 부가가치세는 수입입액 및 지출금액에 포함할 것("매출실적과 입금실적"과 상이한 점에 유의할 것) 2. 전기 이월잔이 수입, 지출은 공란으로 하고 이월잔액만을 기재할 것. 3. 매월의 이월잔 란에느 그 달의 실제 이월잔고를 기재하고 소계, 누계 및 합계의 이월잔 란에는 그때까지의 수입 합계액과 지출 합계액의 차액, 즉 자금수지 실적을 기재할 것. 4. 그 달까지의 누계는 당월까지의 실적∙회생계획의 누계와 그 달성률을 표기할 것.
A29: ='8.시재현황'!A19 -> (註) 시재보유 금액 \202,137,563원중 공탁금 및 퇴직연금 잔액 \41,390,736원을 제외한 실제 가용자금은 \160,746,827원입니다.

Sheet 2-2.자금수지 실적 명세표
A1: 2-2. 자금수지실적명세표
A2: ='2-1.자금수지표(총괄)'!A3 -> (20**. 04. 01. ~ 20**. 04. 30.)
D3: (단위 : 원)
A4: 구분 | B4: 전월실적 | C4: 금월실적 | D4: 증감 | E4: 비고
A6: 전월이월잔액 | B6: 18849890 | C6: =B55 -> 37009489 | D6: =$C$6-B6 -> 18159599
A7: 수입계 | B7: =SUM(B8:B11) -> 88386849 | C7: =SUM(C8:C11) -> 213985911 | D7: =$C$7-B7 -> 125599062 | F7: =C7='3,4 어음수표 및 주요 업무사항'!E81 -> TRUE
A8: 매출입금 | B8: 69156370 | C8: ='3,4 어음수표 및 주요 업무사항'!E81-'3,4 어음수표 및 주요 업무사항'!E82-'3,4 어음수표 및 주요 업무사항'!H82 -> 213685911 | D8: =$C$8-B8 -> 144529541
A9: 영업외 입금 | B9: 19228356 | C9: ='3,4 어음수표 및 주요 업무사항'!E82 -> 300000 | D9: =$C$9-B9 -> -18928356
A10: 이자수익 | B10: 2123 | C10: ='3,4 어음수표 및 주요 업무사항'!H82 -> 0 | D10: =C10-B10 -> -2123
A11: 기타입금 | B11: 0 | C11: 0 | D11: =$C$11-B11 -> 0
A12: 지출계 | B12: =SUM(B13:B53) -> 70227250 | C12: =SUM(C13:C53) -> 90248573 | D12: =$C$12-B12 -> 20021323 | F12: =C12='5.허가사항 내역'!D75 -> TRUE
A13: 회생담보권 | B13: 0 | C13: 0 | D13: =C13-B13 -> 0
A14: 회생채권 | B14: 0 | C14: ='5.허가사항 내역'!J120 -> 0 | D14: =C14-B14 -> 0
A15: 공익채권 | B15: 0 | C15: ='5.허가사항 내역'!J121 -> 0 | D15: =C15-B15 -> 0
A16: 건물관리비 | B16: 0 | C16: ='5.허가사항 내역'!J121 -> 0 | D16: =C16-B16 -> 0
A17: 공구기구비품 | B17: 0 | C17: ='5.허가사항 내역'!J122 -> 0 | D17: =C17-B17 -> 0
A18: 광고선전비 | B18: 29700 | C18: ='5.허가사항 내역'!J123 -> 5000000 | D18: =C18-B18 -> 4970300
A19: 교육훈련비 | B19: 0 | C19: ='5.허가사항 내역'!J124 -> 0 | D19: =C19-B19 -> 0
A20: 도서인쇄비 | B20: 0 | C20: ='5.허가사항 내역'!J125 -> 0 | D20: =C20-B20 -> 0
A21: 미지급급 | B21: 0 | C21: ='5.허가사항 내역'!J126 -> 19160076 | D21: =C21-B21 -> 19160076
A22: 방역비 | B22: 0 | C22: ='5.허가사항 내역'!J127 -> 0 | D22: =C22-B22 -> 0
A23: 보험료 | B23: 566900 | C23: ='5.허가사항 내역'!J128 -> 0 | D23: =C23-B23 -> -566900
A24: 복리후생비 | B24: 2514000 | C24: ='5.허가사항 내역'!J129 -> 1949150 | D24: =C24-B24 -> -564850 | E24: 직원 식대 외
A25: 상여금 | B25: 0 | C25: ='5.허가사항 내역'!J130 -> 0 | D25: =C25-B25 -> 0
A26: 상품 | B26: 682500 | C26: ='5.허가사항 내역'!J131 -> 4116620 | D26: =C26-B26 -> 3434120 | E26: 기업이전관련 가구 구매 외
A27: 생계유지비 | B27: 0 | C27: ='5.허가사항 내역'!J132 -> 0 | D27: =C27-B27 -> 0
A28: 선수금 | B28: 0 | C28: ='5.허가사항 내역'!J133 -> 0 | D28: =C28-B28 -> 0
A29: 세금과공과 | B29: 0 | C29: ='5.허가사항 내역'!J134 -> 18334600 | D29: =C29-B29 -> 18334600 | E29: 2020년 2기 부가가치세(허가 득함)
A30: 소모품비 | B30: 2371790 | C30: ='5.허가사항 내역'!J135 -> 474500 | D30: =C30-B30 -> -1897290 | E30: 기업이전관련 자재 등 구매
A31: 수도광열비 | B31: 0 | C31: ='5.허가사항 내역'!J136 -> 0 | D31: =C31-B31 -> 0
A32: 수선유지비 | B32: 154500 | C32: ='5.허가사항 내역'!J137 -> 0 | D32: =C32-B32 -> -154500
A33: 여비교통비 | B33: 65700 | C33: ='5.허가사항 내역'!J138 -> 324920 | D33: =C33-B33 -> 259220 | E33: 숙소비 외
A34: 예납금 | B34: 0 | C34: ='5.허가사항 내역'!J139 -> 0 | D34: =C34-B34 -> 0
A35: 예수금 | B35: 0 | C35: ='5.허가사항 내역'!J140 -> 0 | D35: =C35-B35 -> 0
A36: 외주용역비 | B36: 32878200 | C36: ='5.허가사항 내역'!J141 -> 12165200 | D36: =C36-B36 -> -20713000 | E36: 기업이전관련 외주용역
A37: 운반비 | B37: 3635620 | C37: ='5.허가사항 내역'!J142 -> 1010940 | D37: =C37-B37 -> -2624680 | E37: 용차비 외
A38: 원부재료비 | B38: 0 | C38: ='5.허가사항 내역'!J143 -> 0 | D38: =C38-B38 -> 0
A39: 이자비용 | B39: 0 | C39: ='5.허가사항 내역'!J144 -> 0 | D39: =C39-B39 -> 0
A40: 일용직급여 | B40: 3504000 | C40: ='5.허가사항 내역'!J145 -> 2755000 | D40: =C40-B40 -> -749000 | E40: 현장 일용직 급여
A41: 임원급여 | B41: 2800000 | C41: ='5.허가사항 내역'!J146 -> 2800000 | D41: =C41-B41 -> 0 | E41: 관리인, CRO 급여
...

Sheet 3,4 어음수표 및 주요 업무사항
A1: 3. 어음 · 수표 발행현황과 자금수지표
A3: 3-1. 어음 발행현황 ☑ 해당없음
A4: 3-2. 수표 발행현황 ☑ 해당없음
A5: 3-3. 당월 말 잔액의 월별 만기 도래액
A6: 발행일 | B6: 지급처 | C6: 어음번호 | D6: 만기일 | E6: 금 액
B9: 없 | C9: 음
A13: 합 계 | E13: =SUM(E7:E12) -> 0
A15: 4. 주요 업무사항
A17: 4-1. 매출실적 현황
E18: (단위 : 원)
A19: 거래일자 | B19: 상 호 | C19: 매 출 금 액 | D19: 적 요 | E19: 비고
A20: 2021-04-01 | B20: 삼**중공업(주) | C20: 1470000 | D20: 삼**중공업 판교사택이사
A21: 2021-04-05 | B21: 바이투셀(Buy to sell) | C21: 600000 | D21: 사무집기 외
A22: 2021-04-05 | B22: 제이모바일 | C22: 500000 | D22: 집기 납품
A23: 2021-04-06 | B23: **시스템(주) | C23: 390000 | D23: **시스템~임원사택 집기폐기 지원
A24: 2021-04-06 | B24: (주)삼**경제연구소 | C24: 1060000 | D24: 사무실~Lay-out 작업
A25: 2021-04-09 | B25: 주식회사 **컴코리아 | C25: 555185 | D25: 03월 전기료
A26: 2021-04-09 | B26: 주식회사 **컴코리아 | C26: 4000000 | D26: 03월 창고임대료
A27: 2021-04-12 | B27: ***디어푸드 주식회사 | C27: 1610000 | D27: ***본사~음성 집기 이전 작업
A28: 2021-04-13 | B28: 삼**물산(주) | C28: 900000 | D28: 삼**건설 이문동 가사사무실 청소작업
A29: 2021-04-14 | B29: 바이투셀(Buy to sell) | C29: 1000000 | D29: 사무집기 외
A30: 2021-04-20 | B30: 삼**물산(주) | C30: 2120000 | D30: 개포현장 작업
A31: 2021-04-20 | B31: 삼**물산(주) | C31: 2140000 | D31: 개포현장 집기~잠실현장 전출
... A39: 2021-04-30 | B39: (주)***신라 | C39: 4900000 | D39: 산업폐기 추가 작업
A40: 2021-04-30 | B40: (주)***신라 | C40: 9460000 | D40: 문서 이전 및 폐기작업 | W40: =114485701-C51 -> 0
A41: 2021-04-30 | B41: (주)***신라 | C41: 2840000 | D41: ***신라 집기이전작업
A42: 2021-04-30 | B42: (주)***신라 | C42: 1700000 | D42: 생명,성우,종이나라~집기 이전
A51: 합 계 | C51: =SUM(C20:C50) -> 114485701 | I51: 세무법인한맘
I52: 현제전자(박춘화) | J52: 63363.89 | N52: 행 레이블 | O52: 합계 : 입 금 액
A53: 4-2. 입금실적 현황 | J53: 1067.4 | N53: 기타 | O53: 3643795
G54: (단위 : 원) | J54: =J52*J53 -> 67634616 | N54: 매출 | O54: 397870465
A55: 구 분 | B55: 입 금 일 | C55: 상 호 | D55: 적요 | E55: 입 금 액 | F55: 기타 | N55: 환급금 | O55: 7871750
A56: 매출 | B56: 44287 | C56: 삼**카드고객서비스 | D56: 3월 작업비 정산 | E56: 162702958 | N56: 이자수익 | O56: 3165
A57: 매출 | B57: 44291 | C57: 제이모바일 | D57: 4월 작업비 정산 | E57: 550000 | N57: 총합계 | O57: 409389175
A58: 매출 | B58: 44292 | C58: 류준영(바이투셀) | D58: 사무집기 판매 | E58: 660000
A59: 매출 | B59: 44295 | C59: (주)***신라 | D59: 3월 작업비 정산 | E59: 3701500 | J59: 7820.2 | K59: 1164.5 | L59: =ROUNDUP(J59*K59,0) -> 9106623
A60: 매출 | B60: 44295 | C60: 김미정(대정프린텍) | D60: 3월 물류비 정산 | E60: 443850 | J60: 6956.43 | K60: 1164.5 | L60: =ROUNDUP(J60*K60,0) -> 8100763
A61: 매출 | B61: 44295 | C61: **시스템㈜ | D61: 3월 작업비 정산 | E61: 1331000 | I61: 기타 | J61: =#REF!+#REF! -> #REF!
A62: 매출 | B62: 44295 | C62: 황라희(루루마켓) | D62: 3월 물류비 정산 | E62: 1848000 | J62: =E81-#REF!-J61 -> #REF!
A63: 매출 | B63: 44298 | C63: (주)**컴코리아 | D63: 3월 창고 임대료 | E63: 4400000
...

Sheet 5.허가사항 내역
A1: 5. 허가사항 내역
A3: 5-1. 허가사항 총괄표
A4: (단위 : 원)
A5: 구 분 | B5: 내 역 | C5: 허가건수 | D5: 금 액 | E5: 비 고
A6: 재판부 허가사항 | B6: 금전관련 | C6: =B27 -> 0건 | D6: =E27 -> 0
B7: 기 타 | C7: =B41 -> 4건 | D7: 0
B8: 소 계 | C8: =COUNTA($A$32:$A$40,$A$21:$A$26)&"건" -> 4건 | D8: =SUM(D6:D7) -> 0
A9: 관리위원 허가사항 | B9: 금전관련 | C9: =B56 -> 3건 | D9: =E56 -> 50275800
B10: 기 타 | C10: =B64 -> 0건 | D10: 0
B11: 소 계 | C11: =COUNTA($B$48:$B$55,$B$62:$B$62)&"건" -> 3건 | D11: =SUM(D9:D10) -> 50275800
A12: 합계 | B12: 금전관련 | C12: =COUNTA(B21:B26,B48:B55)&"건" -> 3건 | D12: =D6+D9 -> 50275800
B13: 기 타 | C13: =COUNTA(A32:A40,A62:A62)&"건" -> 4건 | D13: 0
B14: 합 계 | C14: =COUNTA($A$32:$A$40,$A$21:$A$26,$A$48:$A$55,$A$62:$A$62)&"건" -> 7건 | D14: =SUM(D12:D13) -> 50275800
A16: 5-2. 법원 허가사항 명세
A18: 가) 금전관련 허가사항
G19: (단위 : 원)
A20: 허가일자 | B20: 문서번호 | C20: 제목 | E20: 금액 | F20: 비 고
C21: 없 음
A27: 합계 | B27: =COUNTA(B21:B26)&"건" -> 0건 | E27: =SUM(E21:E26) -> 0
A29: 나) 보고 및 기타 허가사항
A31: 접수일자 | B31: 문서번호 | C31: 제목 | E31: 비 고
A32: 44287 | B32: 2021-04-01 | C32: 2021년 3월 하반월 자금수지상황보고서 제출
A33: 44300 | B33: 2021-04-03 | C33: 2021년 3월 관리인월간보고서 제출
A34: 44302 | B34: 2021-04-04 | C34: 2021년 4월 상반월 자금수지상황보고서 제출
A35: 44312 | B35: 2021-04-07 | C35: 공익채권 변제 결과 보고
A41: 합계 | B41: =COUNTA(A32:A40)&"건" -> 4건
A43: 5-3. 관리위원 허가사항 명세
A45: 가) 금전관련 관리위원 허가사항
F46: (단위 : 원)
A47: 허가일자 | B47: 문서번호 | C47: 제목 | E47: 금액 | F47: 비 고 | H47: =COUNTA(B48:B55)&"건" -> 3건
A48: 44291 | B48: 2021-04-02 | C48: 3월 임직원급여 지급 허가 신청 | E48: 21061680
A49: 44305 | B49: 2021-04-05 | C49: 용역비 등 지급허가 신청 | E49: 11994200
A50: 44312 | B50: 2021-04-06 | C50: 공익채권 변제 허가 신청 | E50: 17219920 | F50: 가산금 포함 18,437,200원 변제
A56: 합계 | B56: =COUNTA($B$48:$B$55)&"건" -> 3건 | E56: =SUM(E48:E55) -> 50275800
A59: 나) 보고 및 기타 관리위원 허가사항(기타신청서 포함)
A61: 접수일자 | B61: 문서번호 | C61: 제목 | E61: 비 고
C62: 없 음
A64: 합계 | B64: =COUNTA(B62:B63)&"건" -> 0건
A66: 6. 금원지출 내역
A68: 6-1. 금원지출 총괄표
...

Sheet 7.공익채권
A1: 7. 공익채권 현황표
A2: (20**. 04. 30. 기준)
J3: (단위 : 원)
A4: 구분 | B4: 개시결정일(2020. 08. 31.) 기준 | C4: 전년도말 | D4: 전분기말 | E4: 전월말 | F4: 당월말 | G4: 개시결정일 (또는 인가일 대비증감) | H4: 전년도말 대비증감 | I4: 전분기말 대비증감 | J4: 전월말 대비증감
A5: 은행 | J5: =F5-E5 -> 0
A6: 보험회사 | J6: =F6-E6 -> 0
A7: 금융기관 공익채권 계 | B7: =SUM(B5:B6) -> 0 | C7: =SUM(C5:C6) -> 0 | D7: =SUM(D5:D6) -> 0 | E7: =SUM(E5:E6) -> 0 | F7: =SUM(F5:F6) -> 0 | G7: =SUM(G5:G6) -> 0 | H7: =SUM(H5:H6) -> 0 | I7: =SUM(I5:I6) -> 0 | J7: =SUM(J5:J6) -> 0
A8: 어음채무 | J8: =F8-E8 -> 0
A9: 매입채무 | E9: 0 | F9: 0 | G9: =F9-B9 -> 0 | J9: =F9-E9 -> 0
A10: 상거래 공익채권계 | B10: =SUM(B8:B9) -> 0 | C10: =SUM(C8:C9) -> 0 | D10: =SUM(D8:D9) -> 0 | E10: =SUM(E8:E9) -> 0 | F10: =SUM(F8:F9) -> 0 | G10: =SUM(G8:G9) -> 0 | H10: =SUM(H8:H9) -> 0 | I10: =SUM(I8:I9) -> 0 | J10: =F10-E10 -> 0
A11: 조세 | J11: =F11-E11 -> 0
A12: 건강보험료 | J12: =F12-E12 -> 0
A13: 제세공과금 공익채권 계 | B13: =SUM(B11:B12) -> 0 | C13: =SUM(C11:C12) -> 0 | D13: =SUM(D11:D12) -> 0 | E13: =SUM(E11:E12) -> 0 | F13: =SUM(F11:F12) -> 0 | G13: =SUM(G11:G12) -> 0 | H13: =SUM(H11:H12) -> 0 | I13: =SUM(I11:I12) -> 0 | J13: =SUM(J11:J12) -> 0
A14: 미지급급여 | B14: 29459146 | C14: 25459146 | D14: 25459146 | E14: 21459146 | F14: 21356526 | G14: =F14-B14 -> -8102620 | H14: =F14-C14 -> -4102620 | I14: =F14-D14 -> -4102620 | J14: =F14-E14 -> -102620
A15: 미지급퇴직금 | B15: 0 | C15: 0 | D15: 0 | E15: 0 | F15: 0 | G15: 0 | H15: 0 | I15: 0 | J15: =F15-E15 -> 0
A16: 노무비 | B16: 0 | C16: 0 | D16: 0 | E16: 0 | F16: 0 | G16: =F16-B16 -> 0 | H16: =F16-C16 -> 0 | I16: =F16-D16 -> 0 | J16: =F16-E16 -> 0
A17: 기타 | J17: =F17-E17 -> 0
A18: 기타 공익채권 계 | B18: =SUM(B14:B17) -> 29459146 | C18: =SUM(C14:C17) -> 25459146 | D18: =SUM(D14:D17) -> 25459146 | E18: =SUM(E14:E17) -> 21459146 | F18: =SUM(F14:F17) -> 21356526 | G18: =SUM(G14:G17) -> -8102620 | H18: =SUM(H14:H17) -> -4102620 | I18: =SUM(I14:I17) -> -4102620 | J18: =SUM(J14:J17) -> -102620
A19: 합계 | B19: =B7+B10+B13+B18 -> 29459146 | C19: =C7+C10+C13+C18 -> 25459146 | D19: =D7+D10+D13+D18 -> 25459146 | E19: =E7+E10+E13+E18 -> 21459146 | F19: =F7+F10+F13+F18 -> 21356526 | G19: =G7+G10+G13+G18 -> -8102620 | H19: =H7+H10+H13+H18 -> -4102620 | I19: =I7+I10+I13+I18 -> -4102620 | J19: =J7+J10+J13+J18 -> -102620
A21: 보유 매출채권 계 | B21: 120013664 | C21: 77326760 | D21: 77326760 | E21: 86086060 | F21: 91570360 | G21: =F21-B21 -> -28443304 | H21: =F21-C21 -> 14243600 | I21: =F21-D21 -> 14243600 | J21: =F21-E21 -> 5484300
A36: 2013. 10. 31 현금시재 소계
A37: 2013. 10. 31. 보통예금 시재 소계

Sheet 8.시재현황
A1: 8. 시재보유 현황
A3: ='7.공익채권'!A2 -> (20**. 04. 30. 기준)
G4: (단위 : 원 )
A5: 구분 | B5: 예적금코드명 | C5: 계좌번호 | D5: 잔 액 | E5: 비고
A6: 현금 | B6: 시재 | D6: 0
A7: 기업자유예탁금 | B7: 농협은행 | C7: 355-00**-***3-83 | D7: 115973502
A8: 기업자유예탁금 | B8: 농협은행 | C8: 355-00**-***0-63 | D8: 3378958
A9: 기업자유예탁금 | B9: 농협은행 | C9: 355-00**-***1-53 | D9: 801
A10: 보통예금 | B10: 신한은행 | C10: 100-***-609*** | D10: 41390736
A11: KB기업종합통장 | B11: 국민은행 | C11: 794***-04-00**** | D11: 1000
A12: 기업자유예금 | B12: 하나은행 | C12: 145-****11-****4 | D12: 1651
A13: 기업자유예금 | B13: 기업은행 | C13: ***-013***-04-*** | D13: 179
A14: 의정부지방법원 고양지원 | B14: 금전공탁서 | C14: 2020년 금 제3***호 | D14: 15051900 | G14: 가용자금 제외(압류 공탁금)
A15: 의정부지방법원 고양지원 | B15: 금전공탁서 | C15: 2020년 금 제***5호 | D15: 14668500 | G15: 가용자금 제외(압류 공탁금)
A16: 의정부지방법원 고양지원 | B16: 배당사실증명서 | C16: 2020년 금 제***6호 | D16: 6453778 | G16: ㈜***케이 가압류 배당 공탁금
A17: 퇴직연금 | B17: 기업은행 | C17: ***-****67-*4-0** | D17: 5216558 | G17: 가용자금 제외
A18: 합 계 | D18: =SUM(D6:D17) -> 202137563
A19: (註) 시재보유 금액 \202,137,563원중 공탁금 및 퇴직연금 잔액 \41,390,736원을 제외한 실제 가용자금은 \160,746,827원입니다. | H19: 예금잔액 | I19: 공탁금&퇴직연금
G20: =D18-I20 -> 160746827 | H20: =G20-D6 -> 160746827 | I20: =SUM(D14:D17) -> 41390736
A23: 구분 | B23: 예적금코드명 | C23: 계좌번호 | D23: 잔 액 | E23: 비고
A30: 합 계 | D30: =SUM(D24:D29) -> 0
D38: =D36+D24 -> 0
I60: 세무법인한맘
I61: 현제전자(박춘화)

Sheet 기업외화
A1: 외화예금거래내역조회
A2: 계좌번호 : 345-052147-56-00010 | E2: 예금종류 : 거주자외화보통예금
A3: 예금주명 : (주)유스테크 | E3: 조회기간 : 2018-01-01 ~ 2018-01-31
A4: No | B4: 거래일시 | C4: 통화 | D4: 입금 | E4: 출금 | F4: 거래후잔액 | G4: 적요 | H4: 수출계좌번호 | I4: 해외수입업자
A5: 1 | B5: 2018-01-05 17:48:45 | C5: USD | D5: 0 | E5: 242 | F5: 699.9 | G5: 외화송금출금
A6: 2 | B6: 2018-01-25 17:24:00 | C6: USD | D6: 0 | E6: 699.9 | F6: 0 | G6: 기타
B7: 합계 | C7: USD | D7: 0 | E7: 941.9
A9: 외화예금거래내역조회
A10: 계좌번호 : 345-052147-56-00010 | E10: 예금종류 : 거주자외화보통예금
A11: 예금주명 : (주)유스테크 | E11: 조회기간 : 2017-12-01 ~ 2017-12-31
A12: No | B12: 거래일시 | C12: 통화 | D12: 입금 | E12: 출금 | F12: 거래후잔액 | G12: 적요 | H12: 수출계좌번호 | I12: 해외수입업자
A13: 1 | B13: 2017-12-07 11:14:01 | C13: USD | D13: 0 | E13: 325 | F13: 74852.55 | G13: 외화송금출금
A14: 2 | B14: 2017-12-08 09:13:13 | C14: USD | D14: 0 | E14: 73000 | F14: 1852.55 | G14: 원화입금
A15: 3 | B15: 2017-12-20 13:03:37 | C15: USD | D15: 15167.8 | E15: 0 | F15: 17020.35 | G15: 해외송금 | I15: XINGKE ELECTRONICS (HK) CO.,LTD
A16: 4 | B16: 2017-12-24 09:35:39 | C16: USD | D16: 0.71 | E16: 0 | F16: 17021.06 | G16: 2017년결산
A17: 5 | B17: 2017-12-27 11:56:11 | C17: USD | D17: 0 | E17: 710.4 | F17: 16310.66 | G17: 외화송금출금
A18: 6 | B18: 2017-12-29 15:38:35 | C18: USD | D18: 54631.24 | E18: 0 | F18: 70941.9 | G18: CELLTECHNOLOGY CO.,LTD.
A19: 7 | B19: 2017-12-29 16:28:58 | C19: USD | D19: 0 | E19: 70000 | F19: 941.9 | G19: 원화입금
B20: 합계 | C20: USD | D20: 69799.75 | E20: 144035.4

Sheet Sheet1

Sheet Sheet2

Sheet 농협(5353-83)
B1: 농협은행
B3: 입출금거래내역조회결과
B4: 현재시간 : 20**년 05월 03일 10시 02분 14초
B5: 계좌번호 | C5: 355-00**-***3-83 | E5: 예금종류 | G5: 기업자유예탁금
B6: 예금주명 | C6: ㈜*****스 | E6: 현재통장잔액 | G6: 0
B7: 조회기간 | C7: 20**/04/01 ~ 20**/04/30 | E7: 현재지급가능잔액 | G7: 0
B8: ● 입출금거래내역 | I8: (단위: 원)
B9: 거래일시 | C9: 출금금액 | D9: 입금금액 | E9: 거래후잔액 | F9: 거래내용 | G9: 거래기록사항 | H9: 거래점 | I9: 이체메모
B10: 2021/04/21 19:05:40 | C10: 735788 | E10: 12441401 | F10: 센터일괄 | G10: 메리츠캐피탈 | H10: 농협 000367 | I10: 출금취소건
B11: 2021/04/22 11:09:14 | D11: 735788 | E11: 13177189 | F11: PC우리은행 | G11: 메리츠㈜** | H11: 우리 0845540 | I11: 출금취소건
B12: 2021/04/23 11:07:01 | C12: 1 | E12: 13177188 | F12: 인터넷당행 | G12: ㈜**로지스틱스 | H12: 농협 215066 | I12: NH(5360-63)으로 이체
B13: 2021/04/23 11:10:43 | C13: 13100000 | E13: 77188 | F13: 인터넷당행 | G13: 계좌통합 | H13: 농협 215066 | I13: NH(5360-63)으로 이체
B14: 2021/04/26 20:19:03 | C14: 77188 | E14: 0 | F14: 자동납부 | G14: BMW | H14: 농협 000002 | I14: 환입예정
B15: 2021/04/30 18:24:49 | D15: 808500 | E15: 808500 | F15: E-하나은행 | G15: (주)동원엔터프라이 | H15: 하나 0812159
B16: 2021/04/30 20:10:35 | C16: 808500 | E16: 0 | F16: 자동납부 | G16: BMW | H16: 농협 000002 | I16: 환입예정
B17: · 고객님이 요청하신 대로 위와 같이 처리되었습니다. · 본 확인증은 고객님의 편의를 위하여 제공되는 것으로 법적 효력은 없습니다. · 농협 인터넷뱅킹을 이용해 주셔서 대단히 감사합니다.

Sheet 농협(5360-63)
B1: 농협은행
B3: 입출금거래내역조회결과
B4: 현재시간 : 20**년 05월 03일 10시 04분 20초
B5: 계좌번호 | C5: 355-00**-***0-63 | E5: 예금종류 | G5: 기업자유예탁금
B6: 예금주명 | C6: ㈜*****스 | E6: 현재통장잔액 | G6: 3117458
B7: 조회기간 | C7: 20**/04/01 ~ 20**/04/30 | E7: 현재지급가능잔액 | G7: 3117458
B8: ● 입출금거래내역 | I8: (단위: 원)
B9: 거래일시 | C9: 출금금액 | D9: 입금금액 | E9: 거래후잔액 | F9: 거래내용 | G9: 거래기록사항 | H9: 거래점 | I9: 이체메모
B10: 2021/04/01 06:06:22 | C10: 21100 | E10: 1355726 | F10: NH체크 | G10: CU**대로점 | H10: 농협 100280 | I10: 취소건
B11: 2021/04/01 06:20:52 | C11: -21100 | E11: 1376826 | F11: NH체크 | G11: CU**대로점 | H11: 농협 100280 | I11: 취소건
B12: 2021/04/01 06:21:14 | C12: 17500 | E12: 1359326 | F12: NH체크 | G12: CU**대로점 | H12: 농협 100280
B13: 2021/04/01 10:24:50 | C13: 4420 | E13: 1354906 | F13: NH체크 | G13: 세븐일레븐(**백현점) | H13: 농협 100280
B14: 2021/04/01 12:51:56 | C14: 25000 | E14: 1329906 | F14: NH체크 | G14: **리두루치기 | H14: 농협 100280
B15: 2021/04/01 13:24:44 | C15: 30000 | E15: 1299906 | F15: NH체크 | G15: **의밥상 | H15: 농협 100280
B16: 2021/04/01 13:33:55 | C16: 22000 | E16: 1277906 | F16: NH체크 | G16: **고깃집 | H16: 농협 100280
B17: 2021/04/01 14:29:30 | C17: 80500 | E17: 1197406 | F17: G-기업은행 | G17: 용** | H17: 농협 100280 | I17: 판교에서 평택가구 이전알바비
B18: 2021/04/01 16:22:03 | C18: 6000 | E18: 1191406 | F18: NH체크 | G18: 세븐일레븐(**백현점) | H18: 농협 100280
B19: 2021/04/01 16:34:56 | C19: 62000 | E19: 1129406 | F19: NH체크 | G19: ***집 | H19: 농협 100280
B20: 2021/04/01 17:26:39 | D20: 407000 | E20: 1536406 | F20: E-우리은행 | G20: **카드고객서비스 | H20: 우리 0845595
B21: 2021/04/01 17:38:51 | C21: 27000 | E21: 1509406 | F21: NH체크 | G21: **의달인 | H21: 농협 100280
B22: 2021/04/01 18:39:11 | C22: 41300 | E22: 1468106 | F22: NH체크 | G22: ****한의원 | H22: 농협 100280
B23: 2021/04/01 19:11:58 | C23: 50000 | E23: 1418106 | F23: NH체크 | G23: **주유소 | H23: 농협 100280
B24: 2021/04/02 12:56:02 | C24: 154500 | E24: 1263606 | F24: G-국민은행 | G24: 개별화물 이** | H24: 농협 100280 | I24: 판교 사택이전용차비
B25: 2021/04/02 12:56:03 | C25: 231000 | E25: 1032606 | F25: 인터넷당행 | G25: **사다리차 강** | H25: 농협 100280 | I25: 보관집기가정이사 사다리차사용
B26: 2021/04/02 12:56:04 | C26: 120000 | E26: 912606 | F26: 인터넷당행 | G26: 양** | H26: 농협 100280 | I26: 판교 사택이사사다리차
B27: 2021/04/02 12:56:05 | C27: 240500 | E27: 672106 | F27: G-신한은행 | G27: 고** | H27: 농협 100280 | I27: 보관집기가정이사 주방용역
B28: 2021/04/02 12:56:06 | C28: 150500 | E28: 521606 | F28: G-카카오 | G28: 이** | H28: 농협 100280 | I28: 김영호 보관집기 가정이사 용역
B29: 2021/04/02 13:26:45 | C29: 8000 | E29: 513606 | F29: NH체크 | G29: 가츠몽**점 | H29: 농협 100280
B30: 2021/04/02 14:58:47 | C30: 30000 | E30: 483606 | F30: NH체크 | G30: **에너지㈜**주유소 | H30: 농협 100280
B31: 2021/04/02 17:35:28 | C31: 144000 | E31: 339606 | F31: NH체크 | G31: 아** | H31: 농협 100280
B32: 2021/04/02 17:48:15 | C32: 1000 | E32: 338606 | F32: NH체크 | G32: ****타워입주자대표운영위원 | H32: 농협 100280
B33: 2021/04/02 19:10:37 | C33: 50000 | E33: 288606 | F33: NH체크 | G33: **주유소 | H33: 농협 100280
B34: 2021/04/02 19:47:57 | C34: 12500 | E34: 276106 | F34: NH체크 | G34: **천국 | H34: 농협 100280
B35: 2021/04/02 20:08:45 | C35: 25400 | E35: 250706 | F35: NH체크 | G35: emart24***거리점 | H35: 농협 100280
B36: 2021/04/03 00:49:16 | C36: 97500 | E36: 153206 | F36: NH체크 | G36: **향 | H36: 농협 100280
B37: 2021/04/03 02:47:53 | C37: 60000 | E37: 93206 | F37: NH체크 | G37: 30개월 | H37: 농협 100280
B38: 2021/04/03 12:52:00 | C38: 8000 | E38: 85206 | F38: NH체크 | G38: **서울해장국**집****점 | H38: 농협 100280
B39: 2021/04/03 18:27:42 | C39: 8000 | E39: 77206 | F39: NH체크 | G39: **왕순대 | H39: 농협 100280
B40: 2021/04/03 22:24:09 | C40: 45000 | E40: 32206 | F40: NH체크 | G40: ***의아침A | H40: 농협 100280
B41: 2021/04/03 22:55:19 | C41: 29000 | E41: 3206 | F41: NH체크 | G41: **치킨금왕점 | H41: 농협 100280
...

Sheet 농협(8661-53)
B1: 농협은행
B3: 입출금거래내역조회결과
B4: 현재시간 : 20**년 05월 03일 10시 12분 43초
B5: 계좌번호 | C5: 355-00**-***1-53 | E5: 예금종류 | G5: 기업자유예탁금
B6: 예금주명 | C6: ㈜*****스 | E6: 현재통장잔액 | G6: 801
B7: 조회기간 | C7: 20**/09/01 ~ 20**/04/30 | E7: 현재지급가능잔액 | G7: 801
B8: ● 입출금거래내역 | I8: (단위: 원)
B9: 거래일시 | C9: 출금금액 | D9: 입금금액 | E9: 거래후잔액 | F9: 거래내용 | G9: 거래기록사항 | H9: 거래점 | I9: 이체메모
B10: 2020/09/27 10:56:49 | D10: 1 | E10: 801 | F10: 예금이자 | H10: 농협 201058
B11: · 고객님이 요청하신 대로 위와 같이 처리되었습니다. · 본 확인증은 고객님의 편의를 위하여 제공되는 것으로 법적 효력은 없습니다. · 농협 인터넷뱅킹을 이용해 주셔서 대단히 감사합니다.

Sheet 신한(609835)
A1: 신한은행
A4: 예금 거래내역 조회
G5: 2021.05.03 10:26:40 현재
A6: 계좌번호 | C6: 100-***-609***
A7: 조회기간 | C7: 2021.04.01~2021.04.30
A8: 조회구분 | C8: 전체
A10: 예금종류 | C10: 보통예금 | F10: 현재잔액 | G10: 0 원
A11: 계좌번호 | C11: 100-032-609835 | F11: 출금가능금액 | G11: 0 원
A12: 고객명 | C12: ㈜*****스 | F12: 연장금액 | G12: 0 원
A13: 최종거래일자 | C13: 20*.04.29 | F13: 대출한도 | G13: 0 원
A14: 대출이자 | C14: 0 원 | F14: 지급제한금액 | G14: 0 원
A16: No | B16: 거래일시 | C16: 적요 | D16: 입금액 | E16: 출금액 | F16: 내용 | G16: 잔액 | H16: 거래점명 | I16: 입금인코드
A17: 1 | B17: 2021.04.27 17:40:57 | C17: 이자수 | D17: 0 | E17: 3,208,523 | F17: 351002189051 | G17: 14,964 | H17: 인천주
A18: 2 | B18: 2021.04.27 17:40:58 | C18: 이자수 | D18: 0 | E18: 10,491 | F18: 351002189075 | G18: 4,473 | H18: 인천주
A19: 3 | B19: 2021.04.27 14:25:10 | C19: 정정 | D19: 0 | E19: -3,208,523 | F19: 351002189051 | G19: 3,212,996 | H19: 인천주
A20: 4 | B20: 2021.04.27 14:25:27 | C20: 정정 | D20: 0 | E20: -10,491 | F20: 351002189075 | G20: 3,223,487 | H20: 인천주
A21: 5 | B21: 2021.04.29 12:41:13 | C21: BZ뱅크 | D21: 0 | E21: 3,222,987 | F21: ㈜****스 | G21: 500 | H21: 인천주 | I21: NH(5360-63)으로 이체
A22: 6 | B22: 2021.04.29 12:41:13 | C22: BZ수수 | D22: 0 | E22: 500 | F22: ㈜****스 | G22: 0 | H22: 인천주
A24: 입금건수 / 입금합계 : 0 건 / 0 원 | F24: 출금건수 / 출금합계 : 6 건 / 3,223,487 원

Sheet 국민(006781)
A1: 국민은행
A3: 예금신탁계좌조회
A5: 입출금이 자유로운 예금계좌
A7: No | B7: 계좌번호 | C7: 계좌명 | D7: 계좌별명 | E7: 신규일 | F7: 잔액(원)
A8: 1 | B8: 794***-04-00**** | C8: 사업자응원통장-기업자유 | E8: 43172 | F8: 1000

Sheet 하나(13904)
A1: 하나은행
A3: 계좌목록
A5: 출력일시 : 2021-05-03 10:33:01
A7: - 입출금
A8: 계좌명(별칭) | B8: 계좌번호 | C8: 구계좌번호 | D8: 신규일 | E8: 최종거래일/만기일 | F8: 잔액
A9: 기업자유예금 | B9: 145-****11-****4 | D9: 2016-07-27 | E9: 2020-01-06 | F9: 1,651
A10: 합계 | F10: 1,651

Sheet 기업(04-018)
A1: 기업은행
A3: 거래내역조회_입출식 예금
A4: 계좌번호 : ***-013***-04-*** | G4: 조회기준일 : 2021년 05월 03일 10:34
A5: 예금주명 : ㈜*****스 | G5: 예금종류 : 기업자유예금(기업섬김통장)
A6: 현재잔액 : 179원 | G6: 출금가능금액 : 0원
A7: 조회시작일자 : 2021-04-01 | G7: 조회종료일자 : 2021-04-30
A8: No | B8: 거래일시 | C8: 출금 | D8: 입금 | E8: 거래후 잔액 | F8: 거래내용 | G8: 상대계좌번호 | H8: 상대은행 | I8: 거래구분 | J8: 수표어음금액 | K8: CMS코드 | L8: 상대계좌예금주명
A9: 1 | B9: 2021-04-19 07:17:36 | C9: 0 | D9: 0 | E9: 179 | F9: 2021년결산 | I9: 이자 | J9: 0
B10: 합계 | C10: 0 | D10: 0

Sheet 기업(94-001)
A1: 기업은행(퇴직연금)
A3: 퇴직연금 인쇄하기
A4: No | B4: 예금구분 | C4: 예금종류 | D4: 계좌번호 | E4: 계좌별명 | F4: 만기일 | G4: 최종거래일 | H4: 잔액
A5: 1 | B5: 퇴직연금 | C5: 확정급여형퇴직연금(DB) | D5: ***-01****-9*-*** | E5: 퇴직연금 | F5: 2016-09-25 | G5: 2020-12-31 | H5: 5216558
H6: 5216558

Sheet 4대보험
B1: 납부액 | C1: 회사부담 | D1: 직원부담 | E1: 합계 | F1: 회사부담율 | G1: 직원부담율
A2: 건강보험료 | B2: 500780 | C2: =B2*50% -> 250390 | D2: =B2*50% -> 250390 | E2: =F2+G2 -> 0.0667 | F2: 0.03335 | G2: 0.03335
A3: 장기요양보험료 | B3: 57640 | C3: =B3*50% -> 28820 | D3: =B3*50% -> 28820 | E3: =F3+G3 -> 0.1025 | F3: 0.05125 | G3: 0.05125
A4: 소계 | B4: =SUM(B2:B3) -> 558420 | C4: =SUM(C2:C3) -> 279210 | D4: =SUM(D2:D3) -> 279210
A5: 연금보험료 | B5: 311840 | C5: =B5*50% -> 155920 | D5: =B5*50% -> 155920 | E5: =F5+G5 -> 0.09 | F5: 0.045 | G5: 0.045
A6: 고용보험료 | B6: 75990 | C6: =B6*F6/E6 -> 43129.459 | D6: =B6-C6 -> 32860.541 | E6: =F6+G6 -> 0.0185 | F6: 0.0105 | G6: 0.008
A7: 산재보험료 | B7: 36260 | C7: =B7 -> 36260 | D7: 0 | F7: 1
A8: 합계 | B8: =SUM(B5:B7)+B4 -> 982510 | C8: =SUM(C5:C7)+C4 -> 514519.46 | D8: =SUM(D5:D7)+D4 -> 467990.54
A10: * 형광표시부분만 입력
A11: * 4대보험료 요율 변경시 변경 요망

Sheet 계정과목
A1: 회생채권 | D1: 운반비
A2: 건물관리비 | D2: 원부재료비
A3: 공구기구비품 | D3: 이자비용
A4: 광고선전비 | D4: 일용직급여
A5: 교육훈련비 | D5: 임원급여
A6: 도서인쇄비 | D6: 잡비
A7: 미지급급 | D7: 재료비
A8: 방역비 | D8: 전력비
A9: 보험료 | D9: 접대비
A10: 복리후생비 | D10: 지급수수료
A11: 상여금 | D11: 지급임차료
A12: 상품 | D12: 직원급여
... A16: 소모품비 | D16: 기타
A17: 수도광열비
A18: 수선유지비
A19: 여비교통비
A20: 여비교통비
A21: 예납금
A22: 예수금
A23: 외주용역비
