Workbook
Name _: #N/A
Name _?: #REF!
Name _??_????æ: #REF!
Name _?__C: #REF!
Name _?__D__BRANCH_\: '[1]8100'!#REF!
Name _?_컛?___i: #REF!
Name _?­p_TOTAL: [3]major!#REF!
Name _?쨲?f: [4]MIP!#REF!
Name _?춑_TOTAL: [5]major!#REF!
Name _?춮t2: [6]현금경비중역!#REF!
Name _?춮ta: [6]현금경비중역!#REF!
Name _?춮tb: [6]현금경비중역!#REF!
Name __: #N/A
Name __?: #REF!
Name __??_????æ: #REF!
Name __?__C: #REF!
Name __?_컛?___i: #REF!
Name __?­p_TOTAL: [3]major!#REF!
Name __?쨲?f: [4]MIP!#REF!
Name __?춑_TOTAL: [5]major!#REF!
Name __?춮t2: [6]현금경비중역!#REF!
Name __?춮ta: [6]현금경비중역!#REF!
Name __?춮tb: [6]현금경비중역!#REF!
Name __________BUN1: #N/A
Name __________BUN2: #REF!
Name __________BUN2: #REF!
Name __________BUN3: #REF!
Name __________BUN3: #REF!
Name __________BUN4: #REF!
Name __________BUN4: #REF!
Name __________SUN1: #REF!
Name __________SUN1: #REF!
Name __________SUN2: #N/A
Name _________BUN1: #N/A
Name _________BUN2: #REF!
Name _________BUN2: #REF!
Name _________BUN3: #REF!
Name _________BUN3: #REF!
Name _________BUN4: #REF!
Name _________BUN4: #REF!
Name _________SUN1: #REF!
Name _________SUN1: #REF!
Name _________SUN2: #N/A
Name ________BUN1: #N/A
Name ________BUN2: #REF!
Name ________BUN2: #REF!
Name ________BUN3: #REF!
Name ________BUN3: #REF!
Name ________BUN4: #REF!
Name ________BUN4: #REF!
Name ________SUN1: #REF!
Name ________SUN1: #REF!
Name ________SUN2: #N/A
Name ________ttt1018: #REF!
Name _______BUN1: #N/A
Name _______BUN2: #REF!
Name _______BUN2: #REF!
Name _______BUN3: #REF!
Name _______BUN3: #REF!
Name _______BUN4: #REF!

Sheet 표지
A1: 서울회생법원 | C1: 제12부(나)
A2: 사건번호 | B2: 20** 회합 100*** 회생
A3: 개시결정일 : 20**. **. **.
A7: 회생담보권자, 회생채권자, 조세·벌금, 주주·지분권자의 목록·신고 및 시부인표
A13: 20**. **. **.
A16: 채무자 *****건설 주식회사
A17: 법률상관리인 대표이사 ***
D156: 0

Sheet 작성기준
A1: 회생담보권자, 회생채권자, 조세·벌금, 주주·지분권자의 시·부인 일반기준
A2: 1. 용어의 정의
A3: 가. 채무자 회생 및 파산에 관한 법률을 이하 “법”이라 함.
A4: 나. 채무자 대양종합건설 주식회사를 “채무자”라함.
A5: 다. 회생 절차 개시 결정일 : 2021. 12. 31.
A6: =""
A7: 2. 회생채권 및 회생담보권의 개념
A8: 가. 회생채권(법 제118조)
A9: 회생채권이란 채무자에 대하여 회생절차 개시전의 원인으로 생긴 재산상의 청구권을 의미함.
A10: 나. 회생담보권(법 제141조)
A11: 회생담보권이란 “회생채권”이나 “회생절차 개시전의 원인으로 생긴 채무자 외의 자에 대한 재산상의 청구권”으로서 회생절차 개시 당시 채무자의 재산상에 존재하는 유치권, 질권, 저당권, 양도 담보권, 가등기 담보권, 전세권, 우선특권으로 담보된 범위의 것을 의미함.
A13: 3. 시·부인 기준에 대한 공통 사항
A14: 가. 공익채권 신고
A15: 회생절차 개시 결정 이후의 원인으로 발생하여 공익채권에 해당하는 채권 신고는 부인함.
A16: 나. 증빙자료 미비
A17: 1) 증비자료 미비는 회사의 채무임을 확인할 수 없는 채권으로 부인 하고, 증빙자료로 첨부된 계약서, 약정서, 세금계산서 등의 내용과 신고한 채권의 내용이 불일치하는 부분은 부인함. 또한 이자지급 약정 없는 채권의 지급이자 신고액도 부인함(단, 회사에서 채권 내용이 확인된 경우에는 시인함).
A18: 2) 채권 신고 시 제출된 증빙자료로 채권자임을 확인할 수 없는 채권신고는 부인함.
A19: 다. 채권양도양수에 의한 채권 신고는 양도자의 채권이 회생회사 채무액과 일치 여부를 확인하여 일치한 경우 시인하고, 일치하지 아니한 경우에는 부인함.
... A44: 마. 회사 부인권 행사 기준일 채무자 회생 및 파산에 관한 법률 제100조의 ‘지급의 정지’ 기준일은 2021. 12. 07.로 함. (끝)
D164: 0

Sheet 목차
A2: 목 차
A4: 1. 회생담보권자, 회생채권자, 조세·벌금, 주주·지분권자의 목록·신고 및 시부인 총괄표 ------------------------------------------------- | K4: 1
A6: 2. 회생담보권 시 · 부인 명세서 -------------------------------------------------------------------------- | K6: 2
A8: 3. 담보물 배분 명세서 --------------------------------------------------------------------------------- | K8: 10
A10: 4. 회생채권 시·부인 명세서 -------------------------------------------------------------------- | K10: 11
A12: 5. 조세·벌금 등의 목록 · 신고 명세서 ---------------------------------------------------------------- | K12: 98
A14: 6. 주주, 지분권자의 목록 · 신고 명세서 -------------------------------------------------------------------------------------------------------------------------------- | K14: 101
A16: 7. 첨부서류
A17: * 감정평가서 - ** 감정평가법인
A18: * 감정평가서 - **** 감정평가법인
A19: * 감정평가서 - ** 감정평가법인 (1)
A20: * 감정평가서 - ** 감정평가법인 (2)
A21: * 국공채평가액
A22: * 건설공제조합 출자좌수 확인원
A23: * 중소기업은행 정기예금 평가액
A24: * 서울보증보험㈜ 미발생구상채권(미확정주채권, 미확정보증채권) 상세내역서
D165: 0

Sheet 1.간지
A6: 1. 회생담보권자, 회생채권자, 조세·벌금, 주주·지분권자의 목록·신고 및 시부인 총괄표
D156: =G150 -> 0

Sheet 1.시부인 총괄표
A1: 1. 회생담보권자, 회생채권자, 조세·벌금, 주주·지분권자의 목록·신고 및 시부인 총괄표
A2: 채무자 : ****건설 주식회사 | H2: (단위 : 원)
A3: 구 분 | C3: 건수 | D3: 신고액, 목록기재액 | E3: 시인액 | F3: 부인액 | G3: 의결권 인정액 | H3: 비고
A4: 회생담보권 | C4: ='2.담보시부인명세'!A89 -> 9 | D4: ='2.담보시부인명세'!K127 -> 202316923718 | E4: ='2.담보시부인명세'!L127 -> 14539327376 | F4: ='2.담보시부인명세'!M127 -> 187777596342 | G4: ='2.담보시부인명세'!N127 -> 14038700635 | H4: 회생담보권 중 회생채권시인액 : 187,777,596,342원 의결권이의액 : 500,626,741원(건설공제조합 미발생구상채권)
A5: 회생 채권 | B5: 회생채권 | C5: ='4. 회생채권자총괄표'!A3459 -> 376 | D5: ='4. 회생채권자총괄표'!G3493 -> 347971012223 | E5: ='4. 회생채권자총괄표'!H3493 -> 96465667806 | F5: ='4. 회생채권자총괄표'!I3493 -> 251505344417 | G5: ='4. 회생채권자총괄표'!J3493 -> 11901719084 | H5: 의결권이의액 : 84,563,948,722원 1. 서울보증보험㈜ : 59,780,198,617원 (미발생 구상채권 및 보증채권) 2. 모가농업협동조합 외 11 : 24,000,000,000원 (아리스타현장 보증채권) 3. ㈜대우건설 외 1 : 783,750,105원 (하자보수분담채권)
B6: 회생담보권 중 회생채권 시인액 | C6: (4) | E6: ='2.담보시부인명세'!O127 -> 187777596342 | F6: =-E6 -> -187777596342 | G6: ='2.담보시부인명세'!P127 -> 3140293151 | H6: 의결권이의액 : 184,637,303,191원 (건설공제조합 미발생구상채권) | I6: =E6-G6 -> 184637303191
B7: 소계 | C7: =SUM(C5:C6) -> 376 | D7: =SUM(D5:D6) -> 347971012223 | E7: =SUM(E5:E6) -> 284243264148 | F7: =SUM(F5:F6) -> 63727748075 | G7: =SUM(G5:G6) -> 15042012235
A8: 합 계 | C8: =C4+C7 -> 385 | D8: =D4+D7 -> 550287935941 | E8: =E4+E7 -> 298782591524 | F8: =F4+F7 -> 251505344417 | G8: =G4+G7 -> 29080712870
H9: (단위 : 원)
A10: 구분 | C10: 건수 | D10: 신고액, 목록기재액 | H10: 비고
A11: 조세채권 | C11: ='5. 조세ㆍ벌금등 채권자의 목록총괄표'!A89 -> 14 | D11: ='5. 조세ㆍ벌금등 채권자의 목록총괄표'!G98 -> 972871880 | H11: 1. 조사 대상이 아님
A12: 주주 및 지분권자 | C12: 5 | D12: 300,000주 (3,000,000,000원) | H12: 1. 조사 대상이 아님 2. 1주당 10,000원
D83: 0

Sheet 2.간지
A9: 2. 회생담보권 시·부인 명세서
D158: =G152 -> 0

Sheet 2.담보시부인명세
A1: ='2.간지'!A9 -> 2. 회생담보권 시·부인 명세서
A2: ='1.시부인 총괄표'!A2 -> 채무자 : ****건설 주식회사
A3: 순번 | B3: 신고 번호 | C3: 목록 번호 | D3: 담보권자 | E3: 주소 | F3: 담보권 종류 및 목적물 | G3: 가치평가 및 배분 | I3: 채권내용 | J3: 신고 | K3: 신고액· 목록기재액 | L3: 시인액 | M3: 부인액 | N3: 의결권 인정액 | O3: 회생채권 시인액 | P3: 회생채권 의결권인정액 | Q3: 시·부인 사유 | R3: 우선권 | S3: 비 고
A4: 1 | B4: 담보권1 | C4: 담보권1-1 | D4: ㈜**은행 (은행장: ***) | F4: 근저당권 1. 대지 인천 중구 북성동1가 98-330 잡종지 667.3㎡ 설정순위:1순위 채권최고액:1,200,000,000 설정일: 2020.05.14. 지상권설정 | G4: 총 평가액 | H4: ='담보물 배분표'!H58 -> 1868440000 | I4: 대여금채권 | Q4: 개시후이자는 회생담보권 부인하고, 회생채권으로 시인하되 의결권 불인정 | S4: 2022. 1. 18. 자 신고로 목록 실효
G5: 선순위 배분액 | H5: 0 | I5: 1) 원금 | J5: 2428340141 | K5: 671751036 | L5: =K5 -> 671751036 | M5: 0 | N5: =L5 -> 671751036 | O5: 0 | P5: 0
G6: 당 배분액 | H6: ='담보물 배분표'!K60 -> 673919783 | I6: 2) 개시전 이자 | J6: 29959124 | K6: 2168747 | L6: =K6 -> 2168747 | M6: 0 | N6: =L6 -> 2168747 | O6: 0 | P6: 0
G7: 배분후 잔액 | H7: =H4-H6-H5 -> 1194520217 | I7: 3) 개시후 이자 | J7: 연4.58%~5.31% | K7: 연12% | L7: 0 | M7: =K7 -> 연12% | N7: 0 | O7: =M7 -> 연12% | P7: 0
I8: 소계 | J8: =SUM(J5:J7) -> 2458299265 | K8: =SUM(K5:K7) -> 673919783 | L8: =SUM(L5:L7) -> 673919783 | M8: =SUM(M5:M7) -> 0 | N8: =SUM(N5:N7) -> 673919783 | O8: =SUM(O5:O7) -> 0 | P8: =SUM(P5:P7) -> 0
C9: 담보권1-2 | F9: 근저당권 1. 대지 경기 하남시 망월동 1155-1 2104.3㎡ 대지권비율 2104.3분의 16.498, 16.498, 17.8319 2. 건물:101호 102호 416호 43.66㎡, 43.66㎡, 47.19㎡ 설정순위:1순위 채권최고액:1,200,000,000 설정일: 2020.06.18. | G9: 총 평가액 | H9: ='담보물 배분표'!H25 -> 1980000000 | I9: 대여금채권 | Q9: 개시후이자는 회생담보권 부인하고, 회생채권으로 시인하되 의결권 불인정 | S9: 2022. 1. 18. 자 신고로 목록 실효
G10: 선순위 배분액 | H10: 0 | I10: 1) 원금 | J10: 2428340141 | K10: 1000000000 | L10: =K10 -> 1000000000 | M10: 0 | N10: =L10 -> 1000000000 | O10: 0 | P10: 0
G11: 당 배분액 | H11: ='담보물 배분표'!K27 -> 1002207944 | I11: 2) 개시전 이자 | J11: 29959124 | K11: 2207944 | L11: =K11 -> 2207944 | M11: 0 | N11: =L11 -> 2207944 | O11: 0 | P11: 0
G12: 배분후 잔액 | H12: =H9-H11-H10 -> 977792056 | I12: 3) 개시후 이자 | J12: 연4.58%~5.31% | K12: 연12% | L12: 0 | M12: =K12 -> 연12% | N12: 0 | O12: =M12 -> 연12% | P12: 0
I13: 소계 | J13: =SUM(J10:J12) -> 2458299265 | K13: =SUM(K10:K12) -> 1002207944 | L13: =SUM(L10:L12) -> 1002207944 | M13: =SUM(M10:M12) -> 0 | N13: =SUM(N10:N12) -> 1002207944 | O13: =SUM(O10:O12) -> 0 | P13: =SUM(P10:P12) -> 0
B14: ㈜**은행 합계 | G14: 총 평가액 | H14: =H4+H9 -> 3848440000 | Q14: 0 | S14: 0
G15: 선순위 배분액 | H15: =H5+H10 -> 0 | I15: 1. 원금 | J15: 0 | K15: =K5+K10 -> 1671751036 | L15: =L5+L10 -> 1671751036 | M15: 0 | N15: =N5+N10 -> 1671751036 | O15: 0 | P15: 0 | S15: 0
G16: 당 배분액 | H16: =H6+H11 -> 1676127727 | I16: 2. 개시전 이자 | J16: 0 | K16: =K6+K11 -> 4376691 | L16: =L6+L11 -> 4376691 | M16: 0 | N16: =N6+N11 -> 4376691 | O16: 0 | P16: 0
G17: 배분후 잔액 | H17: =H7+H12 -> 2172312273 | I17: 3. 개시후 이자 | J17: 0 | K17: =K12 -> 연12% | M17: =M12 -> 연12% | N17: 0 | O17: =O12 -> 연12% | P17: 0
I18: 합계 | J18: =SUM(J15:J17) -> 0 | K18: =SUM(K15:K17) -> 1676127727 | L18: =SUM(L15:L17) -> 1676127727 | M18: =SUM(M15:M17) -> 0 | N18: =SUM(N15:N17) -> 1676127727 | O18: =SUM(O15:O17) -> 0 | P18: 0
A19: 2 | B19: 담보권6 | C19: 담보권2-1 | D19: ****은행 (은행장: ***) | F19: 근저당권 1. 대지 인천 남동구 논현동 636-6 대 825.7㎡ 대지권비율 825.7분의 32.99, 29.08, 41.23, 32.99, 29.08, 41.23, 103.3, 103.3, 102.95, 102.95 2. 건물: 201.202.203.301.302.303.501.601,701.801호.147.51㎡, 130.05㎡, 184.36㎡, 147.51㎡, 130.05㎡ 184.36㎡, 461.92㎡ 461.92㎡, 460.02㎡, 461.44㎡ ①설정순위:1순위 채권최고액:3,600,000,000 설정일: 2018.03.29. ②설정순위:1순위 채권최고액: 672,000,000 설정일: 2018.05.30 | G19: 총 평가액 | H19: ='담보물 배분표'!H8 -> 6666000000 | I19: 대여금채권 | Q19: 개시후이자는 회생담보권 부인하고, 회생채권으로 시인하되 의결권 불인정 | S19: 2022. 1. 27. 자 신고로 목록 실효
G20: 선순위 배분액 | H20: 0 | I20: 1) 원금 | J20: 2428340141 | K20: 2900000000 | L20: =K20 -> 2900000000 | M20: 0 | N20: =L20 -> 2900000000 | O20: 0 | P20: 0
G21: 당 배분액 | H21: ='담보물 배분표'!K10 -> 2914773950 | I21: 2) 개시전 이자 | J21: 29959124 | K21: 14773950 | L21: =K21 -> 14773950 | M21: 0 | N21: =L21 -> 14773950 | O21: 0 | P21: 0
G22: 배분후 잔액 | H22: =H19-H21-H20 -> 3751226050 | I22: 3) 개시후 이자 | J22: 연4.58%~5.31% | K22: 연5.412% | L22: 0 | M22: =K22 -> 연5.412% | N22: 0 | O22: =M22 -> 연5.412% | P22: 0
I23: 소계 | J23: =SUM(J20:J22) -> 2458299265 | K23: =SUM(K20:K22) -> 2914773950 | L23: =SUM(L20:L22) -> 2914773950 | M23: =SUM(M20:M22) -> 0 | N23: =SUM(N20:N22) -> 2914773950 | O23: =SUM(O20:O22) -> 0 | P23: =SUM(P20:P22) -> 0
C24: 담보권2-2 | F24: 근저당권 1. 대지 인천시 중구 북성동1가 98-357, 358. 359, 551 잡종지179.8m2 ,종교용지264.4m2, 잡종지158m2 ,잡종지101.9m2 동소 98-538 대지 135.2m2 2. 건물 인천시 중구 북성동1가 98-538 철근콘크리조 슬라브지붕2층 근린생황시설 1층 87.82m2 2층87.82m2 지하 87.82m2 ①설정순위:1순위 채권최고액:1,560,00,000 설정일: 2021.09.09 | G24: 총 평가액 | H24: ='담보물 배분표'!H69 -> 2290994400 | I24: 대여금채권 | Q24: 개시후이자는 회생담보권 부인하고, 회생채권으로 시인하되 의결권 불인정 | S24: 2022. 1. 27. 자 신고로 목록 실효
G25: 선순위 배분액 | H25: 0 | I25: 1) 원금 | J25: 2428340141 | K25: 1000000000 | L25: =K25 -> 1000000000 | M25: 0 | N25: =L25 -> 1000000000 | O25: 0 | P25: 0
G26: 당 배분액 | H26: ='담보물 배분표'!K71 -> 1008471013 | I26: 2) 개시전 이자 | J26: 29959124 | K26: 8471013 | L26: =K26 -> 8471013 | M26: 0 | N26: =L26 -> 8471013 | O26: 0 | P26: 0
G27: 배분후 잔액 | H27: =H24-H26-H25 -> 1282523387 | I27: 3) 개시후 이자 | J27: 연4.58%~5.31% | K27: 연5.412% | L27: 0 | M27: =K27 -> 연5.412% | N27: 0 | O27: =M27 -> 연5.412% | P27: 0
I28: 소계 | J28: =SUM(J25:J27) -> 2458299265 | K28: =SUM(K25:K27) -> 1008471013 | L28: =SUM(L25:L27) -> 1008471013 | M28: =SUM(M25:M27) -> 0 | N28: =SUM(N25:N27) -> 1008471013 | O28: =SUM(O25:O27) -> 0 | P28: =SUM(P25:P27) -> 0
C29: 담보권2-3 | F29: 1. 대지 경기 용인시 기흥구 서천동 812 대 2672.8㎡ 대지권비율 2672.8의 13.731, 11.369, 11.369, 11.818, 11.818 2. 건물:106호,119호,120호,121호 122호 35.34㎡, 29.26㎡, 29.26㎡, 30.415㎡, 30.415㎡ ①설정순위:1순위 채권최고액:960,000,000 설정일: 2021.07.19 | G29: 총 평가액 | H29: ='담보물 배분표'!H47 -> 1722000000 | I29: 대여금채권 | Q29: 개시후이자는 회생담보권 부인하고, 회생채권으로 시인하되 의결권 불인정 | S29: 2022. 1. 27. 자 신고로 목록 실효
G30: 선순위 배분액 | H30: 0 | I30: 1) 원금 | J30: 2428340141 | K30: 800000000 | L30: =K30 -> 800000000 | M30: 0 | N30: =L30 -> 800000000 | O30: 0 | P30: 0
G31: 당 배분액 | H31: ='담보물 배분표'!K49 -> 805837194 | I31: 2) 개시전 이자 | J31: 29959124 | K31: 5837194 | L31: =K31 -> 5837194 | M31: 0 | N31: =L31 -> 5837194 | O31: 0 | P31: 0
G32: 배분후 잔액 | H32: =H29-H31-H30 -> 916162806 | I32: 3) 개시후 이자 | J32: 연4.58%~5.31% | K32: =K27 -> 연5.412% | L32: 0 | M32: =K32 -> 연5.412% | N32: 0 | O32: =M32 -> 연5.412% | P32: 0
I33: 소계 | J33: =SUM(J30:J32) -> 2458299265 | K33: =SUM(K30:K32) -> 805837194 | L33: =SUM(L30:L32) -> 805837194 | M33: =SUM(M30:M32) -> 0 | N33: =SUM(N30:N32) -> 805837194 | O33: =SUM(O30:O32) -> 0 | P33: =SUM(P30:P32) -> 0
B34: ****은행 합계 | G34: 총 평가액 | H34: =H19+H29+H24 -> 10678994400 | I34: 0 | Q34: 0 | S34: 0
G35: 선순위 배분액 | H35: =H20+H30+H25 -> 0 | I35: 1. 원금 | J35: 0 | K35: =K20+K30+K25 -> 4700000000 | L35: =L20+L30+L25 -> 4700000000 | M35: 0 | N35: =N20+N30+N25 -> 4700000000 | O35: 0 | P35: 0 | S35: 0
G36: 당 배분액 | H36: =H21+H31+H26 -> 4729082157 | I36: 2. 개시전 이자 | J36: 0 | K36: =K21+K31+K26 -> 29082157 | L36: =L21+L31+L26 -> 29082157 | M36: 0 | N36: =N21+N31+N26 -> 29082157 | O36: 0 | P36: 0
G37: 배분후 잔액 | H37: =H22+H32+H27 -> 5949912243 | I37: 3. 개시후 이자 | J37: 0 | K37: =K32 -> 연5.412% | M37: =M32 -> 연5.412% | N37: 0 | O37: =O32 -> 연5.412% | P37: 0
I38: 합계 | J38: =SUM(J35:J37) -> 0 | K38: =SUM(K35:K37) -> 4729082157 | L38: =SUM(L35:L37) -> 4729082157 | M38: =SUM(M35:M37) -> 0 | N38: =SUM(N35:N37) -> 4729082157 | O38: =SUM(O35:O37) -> 0 | P38: 0
A39: 3 | B39: 담보권5 | C39: 담보권3 | F39: 근저당권 1. 대지 세종 나성동 821 대 6097.9㎡ 대지권비율 6097.9분의 17.77, 17.77, 20.26, 20.25, 16.34, 14.53, 18.2, 29, 27.57 2. 건물: 701,801,901,1001,B124A,B126, B127,B214,B215 39.65㎡, 39.65㎡, 45.18㎡, 45.18㎡, 36.44㎡, 32.41㎡, 40.6㎡, 64.69㎡, 61.51㎡ ①설정순위:1순위 채권최고액: 2,700,000,000 설정일: 2020.12.15. | G39: 총 평가액 | H39: ='담보물 배분표'!H36 -> 4489000000 | I39: 대여금채권 | Q39: 개시후이자는 회생담보권 부인하고, 회생채권으로 시인하되 의결권 불인정 | S39: 2022. 1. 27. 자 신고로 목록 실효
G40: 선순위 배분액 | H40: 0 | I40: 1. 원금 | J40: 2428340141 | K40: 2108560759 | L40: =K40 -> 2108560759 | M40: 0 | N40: =L40 -> 2108560759 | O40: 0 | P40: 0
...

Sheet 3.간지
A9: 3. 담보물 배분 명세서
D156: =G150 -> 0

Sheet 담보물 배분표
B3: ='3.간지'!A9 -> 3. 담보물 배분 명세서
B4: ='2.담보시부인명세'!A2 -> 채무자 : ****건설 주식회사
M5: (단위 : 원)
B6: 담보물소재지 | C6: 토지면적/건물면적 | D6: 담보제공현황 | H6: 가치평가액 주1) | I6: 배분금액 | M6: 비고
D7: 순위 | E7: 설정일자 | F7: 채권자 | G7: 공담
C8: 1. 대지 인천 남동구 논현동 636-6 대 825.7㎡ 대지권비율 825.7분의 32.99, 29.08, 41.23, 32.99, 29.08, 41.23, 103.3, 103.3, 102.95, 102.95 2. 건물: 147.51㎡, 130.05㎡, 184.36㎡, 147.51㎡, 130.05㎡, 184.36㎡, 461.92㎡ 461.92㎡, 460.02㎡, 461.44㎡ | D8: 1 | E8: 2018.03.29. | G8: 공담 제2018-513호 | H8: 6666000000 | I8: 1순위
I9: 설정자 | J9: 설정금액 | K9: 배분액 | L9: 배분잔액
J10: 3600000000 | K10: =2900000000+14773950 -> 2914773950 | L10: =H8-K10 -> 3751226050
D11: 2 | E11: 2018.05.30. | G11: 공담 제2018-938호 | I11: 2순위
I12: 설정자 | J12: 설정금액 | K12: 배분액 | L12: 배분잔액
J13: 672000000 | K13: 0 | L13: =L10-K13 -> 3751226050
D14: 3 | E14: 2021.11.30. | G14: 공담 제2021-2707호 | I14: 3순위
I15: 설정자 | J15: 설정금액 | K15: 배분액 | L15: 배분잔액
J16: 1440000000 | K16: 0 | L16: =L13-K16 -> 3751226050
D17: 4 | E17: 2021.11.30. | G17: 공담 제2021-2708호 | I17: 4순위
I18: 설정자 | J18: 설정금액 | K18: 배분액 | L18: 배분잔액
J19: 1320000000 | K19: 0 | L19: =L16-K19 -> 3751226050
B20: 주1) 담보물 가치평가:가람 감정평가법인(2021.11.09기준, 가람 0421-11-40104), 경일감정 평가법인(경일(경인)14-211105-201) 中 높은 감정금액으로 반영함
B23: 담보물소재지 | C23: 토지면적/건물면적 | D23: 담보제공현황 | H23: 가치평가액 주1) | I23: 배분금액 | M23: 비고
D24: 순위 | E24: 설정일자 | F24: 채권자 | G24: 공담
C25: 1. 대지 경기 하남시 망월동 1155-1 대 2104.3㎡ 대지권비율 2104.3분의 16.498, 16.498, 17.8319 2. 건물: 43.66㎡, 43.66㎡, 47.19㎡ | D25: 1 | E25: 2020.06.18. | G25: 공담 | H25: 1980000000 | I25: 1순위
I26: 설정자 | J26: 설정금액 | K26: 배분액 | L26: 배분잔액
J27: 1200000000 | K27: 1002207944 | L27: =H25-K27 -> 977792056
B31: 주1) 담보물 가치평가:리얼티뱅크 감정평가법인
B34: 담보물소재지 | C34: 토지면적/건물면적 | D34: 담보제공현황 | H34: 가치평가액 주1) | I34: 배분금액 | M34: 비고
D35: 순위 | E35: 설정일자 | F35: 채권자 | G35: 공담
C36: 1. 대지 세종 나성동 821 대 6097.9㎡ 대지권비율 6097.9분의 17.77, 17.77, 20.26, 20.25, 16.34, 14.53, 18.2, 29, 27.57 2. 건물: 39.65㎡, 39.65㎡, 45.18㎡, 45.18㎡, 36.44㎡, 32.41㎡, 40.6㎡, 64.69㎡, 61.51㎡ | D36: 1 | E36: 2020.12.15. | G36: 공담 제2020-906호 | H36: 4489000000 | I36: 1순위
I37: 설정자 | J37: 설정금액 | K37: 배분액 | L37: 배분잔액
J38: 2700000000 | K38: =2108560759+13954324 -> 2122515083 | L38: =H36-K38 -> 2366484917
B42: 주1) 담보물 가치평가:리얼티뱅크 감정평가법인
B45: 담보물소재지 | C45: 토지면적/건물면적 | D45: 담보제공현황 | H45: 가치평가액 주1) | I45: 배분금액 | M45: 비고
D46: 순위 | E46: 설정일자 | F46: 채권자 | G46: 공담
C47: 1. 대지 경기 용인시 기흥구 서천동 812 대 2672.8㎡ 대지권비율 2672.8의 13.731, 11.369, 11.369, 11.818, 11.818 2. 건물: 35.34㎡, 29.26㎡, 29.26㎡, 30.415㎡, 30.415㎡ | D47: 1 | E47: 2021.07.19. | G47: 공담 제2021-1464호 | H47: 1722000000 | I47: 1순위
I48: 설정자 | J48: 설정금액 | K48: 배분액 | L48: 배분잔액
J49: 960000000 | K49: =800000000+5837194 -> 805837194 | L49: =H47-K49 -> 916162806
B53: 주1) 담보물 가치평가:리얼티뱅크 감정평가법인
B56: 담보물소재지 | C56: 토지면적/건물면적 | D56: 담보제공현황 | H56: 가치평가액 (주2) | I56: 배분금액 | M56: 비고
D57: 순위 | E57: 설정일자 (주1) | F57: 채권자 | G57: 공담
C58: 1. 대지 인천 중구 북성동1가 98-330 잡종지 667.3㎡ | D58: 1 | E58: 2020.05.14. | G58: 단독 | H58: 1868440000 | I58: 1순위
I59: 설정자 | J59: 설정금액 | K59: 배분액 | L59: 배분잔액
...

Sheet 4.간지
A8: 4. 회생채권 시 · 부인 명세서
D155: =G149 -> 0

Sheet 4. 회생채권자총괄표
A1: ='4.간지'!A8 -> 4. 회생채권 시 · 부인 명세서
A2: ='2.담보시부인명세'!A2 -> 채무자 : ****건설 주식회사 | M2: (단위 : 원)
A3: 순번 | B3: 신고 번호 | C3: 목록 번호 | D3: 채권자 | E3: 주소 | F3: 채권내용 | G3: 신고액· 목록기재액 | H3: 시인액 | I3: 부인액 | J3: 의결권 인정액 | K3: 시·부인 사유 | L3: 우선권 | M3: 비 고
A4: 1 | B4: 채권1 | C4: 채권322-4 | F4: 보증채권(채무인수) | K4: 정확한 채권금액 확인을 위해 일응 부인함 | L4: 0 | M4: OO OO 상업시설 개발사업 주채무자 : ㈜OO
F5: 1. 원금 | G5: 6000000000 | H5: 0 | I5: =G5 -> 6000000000 | J5: 0 | N5: =G5 -> 6000000000 | O5: =H5 -> 0 | P5: =I5 -> 6000000000 | Q5: =J5 -> 0
F6: 2. 개시전 이자 | G6: 0 | H6: 0 | I6: 0 | J6: =H6 -> 0
F7: 3. 개시후 이자 | G7: 0 | H7: 0 | I7: 0 | J7: =H7 -> 0
F8: 합계 | G8: =SUM(G5:G7) -> 6000000000 | H8: =SUM(H5:H7) -> 0 | I8: =SUM(I5:I7) -> 6000000000 | J8: =SUM(J5:J7) -> 0
A9: =A4+1 -> 2 | B9: 채권2 | C9: 채권246 | F9: 상거래채권 | L9: 0 | M9: 2022.1.12 자 신고로 목록 실효 신고번호 채권 4 어음번호: 08820211007000002425, 발행일자:2021.10.07, 만기일자: 2022.01.05 최초수취인: ㈜OO아이디 부도전자어음보유확인서 확인(2022.01.11)
F10: 1. 원금 | G10: 4000000 | H10: =G10 -> 4000000 | I10: 0 | J10: =H10 -> 4000000 | N10: =G10 -> 4000000 | O10: =H10 -> 4000000 | P10: =I10 -> 0 | Q10: =J10 -> 4000000
F11: 2. 개시전 이자 | G11: 0 | H11: 0 | I11: 0 | J11: =H11 -> 0
F12: 3. 개시후 이자 | G12: 0 | H12: 0 | I12: 0 | J12: =H12 -> 0
F13: 합계 | G13: =SUM(G10:G12) -> 4000000 | H13: =SUM(H10:H12) -> 4000000 | I13: =SUM(I10:I12) -> 0 | J13: =SUM(J10:J12) -> 4000000
A14: =A9+1 -> 3 | B14: 채권3 | C14: 채권117 | F14: 신용카드채권 | L14: 0 | M14: 2022.1.12 자 신고로 목록실효
F15: 1. 원금 | G15: 7498480 | H15: =G15 -> 7498480 | I15: 0 | J15: =H15 -> 7498480 | N15: =G15 -> 7498480 | O15: =H15 -> 7498480 | P15: =I15 -> 0 | Q15: =J15 -> 7498480
F16: 2. 개시전 이자 | G16: 8468 | H16: =G16 -> 8468 | I16: 0 | J16: =H16 -> 8468
F17: 3. 개시후 이자 | G17: 0 | H17: 0 | I17: 0 | J17: =H17 -> 0
F18: 합계 | G18: =SUM(G15:G17) -> 7506948 | H18: =SUM(H15:H17) -> 7506948 | I18: =SUM(I15:I17) -> 0 | J18: =SUM(J15:J17) -> 7506948
A19: =A14+1 -> 4 | B19: 채권4 | C19: 채권10 | F19: 상거래채권 | L19: 0 | M19: 2022.1.13 자 신고로 목록 실효
F20: 1. 원금 | G20: 5940000 | H20: =G20 -> 5940000 | I20: 0 | J20: =H20 -> 5940000 | N20: =G20 -> 5940000 | O20: =H20 -> 5940000 | P20: =I20 -> 0 | Q20: =J20 -> 5940000
F21: 2. 개시전 이자 | G21: 0 | H21: 0 | I21: 0 | J21: =H21 -> 0
F22: 3. 개시후 이자 | G22: 0 | H22: 0 | I22: 0 | J22: =H22 -> 0
F23: 합계 | G23: =SUM(G20:G22) -> 5940000 | H23: =SUM(H20:H22) -> 5940000 | I23: =SUM(I20:I22) -> 0 | J23: =SUM(J20:J22) -> 5940000
A24: =A19+1 -> 5 | B24: 채권5 | C24: 채권223 | F24: 상거래채권 | L24: 0 | M24: 2022. 1. 14. 자 신고로 목록 실효
F25: 1. 원금 | G25: 26427500 | H25: =G25 -> 26427500 | I25: 0 | J25: =H25 -> 26427500 | N25: =G25 -> 26427500 | O25: =H25 -> 26427500 | P25: =I25 -> 0 | Q25: =J25 -> 26427500
F26: 2. 개시전 이자 | G26: 0 | H26: 0 | I26: 0 | J26: =H26 -> 0
F27: 3. 개시후 이자 | G27: 0 | H27: 0 | I27: 0 | J27: =H27 -> 0
F28: 합계 | G28: =SUM(G25:G27) -> 26427500 | H28: =SUM(H25:H27) -> 26427500 | I28: =SUM(I25:I27) -> 0 | J28: =SUM(J25:J27) -> 26427500
A29: =A24+1 -> 6 | B29: 채권6-1 | C29: 채권215-1 | F29: 상거래채권 | K29: 어음원본 확인할 수 없어 일응 부인함 | L29: 0 | M29: 2022. 1. 17. 자 신고로 목록 실효 1. 신고번호 채권 8-1 어음번호: 08820211110000005445, 발행일자:2021.11.10, 만기일자: 2022.02.08 최초수취인: ㈜OO스톤 OO은행[신고번호:채권63]앞 배서양도(어음할인) 220,000,000원
F30: 1. 원금 | G30: 254000000 | H30: 0 | I30: =G30 -> 254000000 | J30: =H30 -> 0 | N30: =G30 -> 254000000 | O30: =H30 -> 0 | P30: =I30 -> 254000000 | Q30: =J30 -> 0
F31: 2. 개시전 이자 | G31: 0 | H31: 0 | I31: 0 | J31: =H31 -> 0
F32: 3. 개시후 이자 | G32: 0 | H32: 0 | I32: 0 | J32: =H32 -> 0
F33: 합계 | G33: =SUM(G30:G32) -> 254000000 | H33: =SUM(H30:H32) -> 0 | I33: =SUM(I30:I32) -> 254000000 | J33: =SUM(J30:J32) -> 0
B34: 채권6-2 | C34: 채권215-2 | F34: 상거래채권 | K34: 채무없음으로 일응 부인함 | L34: 0
F35: 1. 원금 | G35: 40700000 | H35: 0 | I35: =G35 -> 40700000 | J35: =H35 -> 0 | N35: =G35 -> 40700000 | O35: =H35 -> 0 | P35: =I35 -> 40700000 | Q35: =J35 -> 0
F36: 2. 개시전 이자 | G36: 0 | H36: 0 | I36: 0 | J36: =H36 -> 0
F37: 3. 개시후 이자 | G37: 0 | H37: 0 | I37: 0 | J37: =H37 -> 0
F38: 합계 | G38: =SUM(G35:G37) -> 40700000 | H38: =SUM(H35:H37) -> 0 | I38: =SUM(I35:I37) -> 40700000 | J38: =SUM(J35:J37) -> 0
B39: ***합계
F40: 1. 원금 | G40: =G30+G35 -> 294700000 | H40: =H30+H35 -> 0 | I40: =I30+I35 -> 294700000 | J40: =J30+J35 -> 0
...

Sheet 5.간지
A9: 5. 조세·벌금 등의 목록 · 신고 명세서
D158: =G152 -> 0

Sheet 5. 조세ㆍ벌금등 채권자의 목록총괄표
A1: ='5.간지'!A9 -> 5. 조세·벌금 등의 목록 · 신고 명세서
A2: ='4. 회생채권자총괄표'!A2 -> 채무자 : ****건설 주식회사 | H2: (단위 : 원)
A3: 순번 | B3: 신고 번호 | C3: 목록 번호 | D3: 채권자 | E3: 주소 | F3: 채권내용 | G3: 금액 | H3: 비 고
A4: 1 | B4: 조세 1-1 | C4: 조세2 | F4: 주민세 | H4: 1. 2022. 1. 25. 자 신고 2. 부과일 : 2021년 11 3. 납기일 : 2022. 1. 31. 2021년 11월 특별징수분 근로소득 2022.1.18 법원허가후 변제 1,653,890원
F5: 1) 본세 | G5: 1653890
F6: 2) 가산금 | G6: 0
F7: 3) 중가산금 | G7: 0
F8: 소계 | G8: =SUM(G5:G7) -> 1653890
B9: 조세 1-2 | F9: 등록면허세 | H9: 1. 2022. 1. 25. 자 신고 2. 부과일 : 2022년 1월 3. 납기일 : 2022. 1. 31. 2022년 등록면허세
F10: 1) 본세 | G10: 499500
F11: 2) 가산금 | G11: 0
F12: 3) 중가산금 | G12: 0
F13: 소계 | G13: =SUM(G10:G12) -> 499500
B14: 부천시 합계
F15: 1. 본세 | G15: =G5+G10 -> 2153390
F16: 2. 가산금 | G16: =G6+G11 -> 0
F17: 3. 중가산금 | G17: =G7+G12 -> 0
F18: 합계 | G18: =SUM(G15:G17) -> 2153390
A19: 2 | B19: 조세 2 | C19: 조세1 | F19: 법인세 | H19: 1. 2021. 1. 27. 자 신고 2. 납기일 : 2022. 2. 3.
F20: 1) 본세 | G20: 720987790
F21: 2) 가산금 | G21: 114637050
F22: 3) 중가산금 | G22: 0
F23: 소계 | G23: =SUM(G20:G22) -> 835624840
A24: 3 | C24: 조세3 | F24: 지방소득세 | H24: 1. 2021. 9. 9. 자 신고 2. 부과일 : 2021년 7월 , 8월 3. 납기일 : 2020. 9. 10. 2021년 11월 특별징수분 근로소득 2022.1.18 법원허가후 변제
F25: 1) 본세 | G25: 258720
F26: 2) 가산금 | G26: 9500
F27: 3) 중가산금 | G27: 0
F28: 소계 | G28: =SUM(G25:G27) -> 268220
A29: 4 | C29: 조세4 | F29: 지방소득세 | H29: 1. 2021. 9. 9. 자 신고 2. 부과일 : 2021년 7월 , 8월 3. 납기일 : 2020. 9. 10. 2021년 11월 특별징수분 근로소득 2022.1.18 법원허가후 변제
F30: 1) 본세 | G30: 19220
F31: 2) 가산금 | G31: 690
F32: 3) 중가산금 | G32: 0
F33: 소계 | G33: =SUM(G30:G32) -> 19910
A34: 5 | C34: 조세5 | F34: 지방소득세 | H34: 1. 2021. 9. 9. 자 신고 2. 부과일 : 2021년 7월 , 8월 3. 납기일 : 2020. 9. 10. 2021년 11월 특별징수분 근로소득 2022.1.18 법원허가후 변제
F35: 1) 본세 | G35: 130230
F36: 2) 가산금 | G36: 4770
F37: 3) 중가산금 | G37: 0
F38: 소계 | G38: =SUM(G35:G37) -> 135000
A39: 6 | C39: 조세6 | F39: 지방소득세 | H39: 1. 2021. 9. 9. 자 신고 2. 부과일 : 2021년 7월 , 8월 3. 납기일 : 2020. 9. 10. 2021년 11월 특별징수분 근로소득 2022.1.18 법원허가후 변제
F40: 1) 본세 | G40: 32800
...

Sheet 6.간지
A5: ='6. 주주, 지분권자의 목록 총괄표'!A1 -> 6. 주주, 지분권자의 목록 · 신고 명세서

Sheet 6. 주주, 지분권자의 목록 총괄표
A1: 6. 주주, 지분권자의 목록 · 신고 명세서
A3: ='5. 조세ㆍ벌금등 채권자의 목록총괄표'!A2 -> 채무자 : ****건설 주식회사 | J3: (단위 : 원)
A4: 순번 | B4: 신고 번호 | C4: 목록 번호 | D4: 주주, 지분권자 | E4: 주소 | F4: 주식출자지분의 종류 | G4: 주식수 | H4: 금액 | I4: 비율 | J4: 비 고
A5: 1 | C5: 주주 등 1 | F5: 보통주식 | G5: 31439 | H5: =G5*10000 -> 314390000 | I5: =G5/$G$10 -> 0.10479667
A6: 2 | C6: 주주 등 2 | F6: 보통주식 | G6: 132541 | H6: =G6*10000 -> 1325410000 | I6: =G6/$G$10 -> 0.44180333
A7: 3 | C7: 주주 등 3 | F7: 보통주식 | G7: 54783 | H7: =G7*10000 -> 547830000 | I7: =G7/$G$10 -> 0.18261
A8: 4 | C8: 주주 등 4 | F8: 보통주식 | G8: 42765 | H8: =G8*10000 -> 427650000 | I8: =G8/$G$10 -> 0.14255
A9: 5 | C9: 주주 등 5 | F9: 보통주식 | G9: 38472 | H9: =G9*10000 -> 384720000 | I9: =G9/$G$10 -> 0.12824
A10: 합계 | G10: =SUBTOTAL(9,G5:G9) -> 300000 | H10: =SUBTOTAL(9,H5:H9) -> 3000000000 | I10: =SUBTOTAL(9,I5:I9) -> 1
A11: 주1) 1주당 금액 : 10,000원 주2) 주주명부 기준일 : 회생절차 개시결정일

Sheet 7.첨부간지
A6: 7. 첨부서류
B9: =목차!A17 -> * 감정평가서 - ** 감정평가법인
B10: =목차!A18 -> * 감정평가서 - **** 감정평가법인
B11: =목차!A19 -> * 감정평가서 - ** 감정평가법인 (1)
B12: =목차!A20 -> * 감정평가서 - ** 감정평가법인 (2)
B13: =목차!A21 -> * 국공채평가액
B14: =목차!A22 -> * 건설공제조합 출자좌수 확인원
B15: =목차!A23 -> * 중소기업은행 정기예금 평가액
B16: =목차!A24 -> * 서울보증보험㈜ 미발생구상채권(미확정주채권, 미확정보증채권) 상세내역서
D158: =G152 -> 0
